<!-- ロボットの名前 -->
<robot name="diff_drive_robot">
  <!-- ロボットの基準とするベースリンク -->
  <link name="base_link"/>

  <!-- ボディの作成 -->
  <link name="body">
    <visual>
      <geometry>
        <cylinder radius="0.2" length="0.15"/>
      </geometry>
      <origin xyz="0 0 0" rpy="0 0 0"/>
      <material name="red">
        <color rgba="1.0 0.0 0.0 1.0"/>
      </material>
    </visual>
    <collision>
      <origin rpy="0 0 0" xyz="0 0 0.0"/>
      <geometry>
        <cylinder radius="0.2" length="0.15"/>]
      </geometry>
    </collision>
    <!--慣性-->
    <inertial>
        <mass value="1.0"/>
        <inertia ixx="0.011875000000000002" iyy="0.011875000000000002" izz="0.020000000000000004" ixy="0" ixz="0" iyz="0"/>
    </inertial>
  </link>

  <!-- タイヤの作成 -->
  <link name="wheel_left">
    <visual>
      <geometry>
        <cylinder radius="0.15" length="0.05"/>
      </geometry>
      <origin xyz="0 0 0" rpy="0 0 0"/>
      <material name="blue">
        <color rgba="0.0 0.0 1.0 1.0"/>
      </material>
    </visual>
    <collision>
      <origin rpy="0 0 0" xyz="0 0 0.0"/>
      <geometry>
        <cylinder radius="0.15" length="0.05"/>]
      </geometry>
    </collision>
    <!--慣性-->
    <inertial>
        <mass value="0.5"/>
        <inertia ixx="0.002916666666666667" iyy="0.002916666666666667" izz="0.005625" ixy="0" ixz="0" iyz="0"/>
    </inertial>
  </link>


  <!-- タイヤの作成 -->
  <link name="wheel_right">
    <visual>
      <geometry>
        <cylinder radius="0.15" length="0.05"/>
      </geometry>
      <origin xyz="0 0 0" rpy="0 0 0"/>
      <material name="cyan">
        <color rgba="0.0 1.0 1.0 1.0"/>
      </material>
    </visual>
    <collision>
      <origin rpy="0 0 0" xyz="0 0 0.0"/>
      <geometry>
        <cylinder radius="0.15" length="0.05"/>
      </geometry>
    </collision>
    <!--慣性-->
    <inertial>
        <mass value="0.5"/>
        <inertia ixx="0.002916666666666667" iyy="0.002916666666666667" izz="0.005625" ixy="0" ixz="0" iyz="0"/>
    </inertial>
  </link>


  <!-- キャスターの作成 -->
  <link name="caster_forward">
    <visual>
      <geometry>
        <sphere radius="0.05"/>
      </geometry>
      <origin xyz="0 0 0" rpy="0 0 0"/>
      <material name="green">
        <color rgba="0.0 1.0 0.0 1.0"/>
      </material>
    </visual>
    <collision>
      <origin rpy="0 0 0" xyz="0 0 0.0"/>
      <geometry>
        <sphere radius="0.05"/>
      </geometry>
    </collision>
    <!--慣性-->
    <inertial>
        <mass value="0.5"/>
        <inertia ixx="3.000e-4" iyy="3.000e-4" izz="3.000e-4" ixy="0" ixz="0" iyz="0"/>
    </inertial>
  </link>
  
  <!-- キャスターの作成 -->
  <link name="caster_backward">
    <visual>
      <geometry>
        <sphere radius="0.05"/>
      </geometry>
      <origin xyz="0 0 0" rpy="0 0 0"/>
      <material name="black">
        <color rgba="0.0 0.0 0.0 1.0"/>
      </material>
    </visual>
    <collision>
      <origin rpy="0 0 0" xyz="0 0 0.0"/>
      <geometry>
        <sphere radius="0.05"/>
      </geometry>
    </collision>
    <!--慣性-->
    <inertial>
        <mass value="0.5"/>
        <inertia ixx="3.000e-4" iyy="3.000e-4" izz="3.000e-4" ixy="0" ixz="0" iyz="0"/>
    </inertial>
  </link>

  <!-- Lidar台の作成 -->
  <link name="lidar_base">
    <visual>
      <geometry>
        <box size="0.1 0.1 0.1"/>
      </geometry>
      <origin xyz="0 0 0" rpy="0 0 0"/>
      <material name="yellow">
        <color rgba="1.0 1.0 0.0 1.0"/>
      </material>
    </visual>
    <collision>
      <origin rpy="0 0 0" xyz="0 0 0.0"/>
      <geometry>
        <box size="0.1 0.1 0.1"/>
      </geometry>
    </collision>
    <!--慣性-->
    <inertial>
        <mass value="0.15"/>
        <inertia ixx="0.25" iyy="0.25" izz="0.25" ixy="0" ixz="0" iyz="0"/>
    </inertial>
  </link>

  <!-- Lidarの作成 -->
  <link name="lidar_link">
    <visual>
      <geometry>
        <cylinder radius="0.05" length="0.05"/>
      </geometry>
      <origin xyz="0 0 0" rpy="0 0 0"/>
      <material name="purple">
        <color rgba="1.0 0.0 1.0 1.0"/>
      </material>
    </visual>
    <collision>
      <origin rpy="0 0 0" xyz="0 0 0.0"/>
      <geometry>
        <cylinder radius="0.05" length="0.05"/>
      </geometry>
    </collision>
    <!--慣性-->
    <inertial>
        <mass value="0.15"/>
        <inertia ixx="0.125" iyy="0.125" izz="0.188" ixy="0" ixz="0" iyz="0"/>
    </inertial>
  </link>
<!-- ################# ジョイント設定 ################## -->

	<joint name="base_joint" type="fixed">
    <origin xyz="0 0 0.15" rpy="0 0 0"/>
    <parent link="base_link"/>
    <child link="body"/>
 	</joint>

	<joint name="wheel_left_joint" type="continuous">
    <axis xyz="0 0 1"/>
    <origin xyz="0 -0.225 0" rpy="1.57 0 0"/>
    <parent link="body"/>
    <child link="wheel_left"/>
 	</joint>

	<joint name="wheel_right_joint" type="continuous">
    <axis xyz="0 0 1"/>
    <origin xyz="0 0.225 0" rpy="1.57 0 0"/>
    <parent link="body"/>
    <child link="wheel_right"/>
	</joint>

	<joint name="caster_forward_joint" type="fixed">
    <origin xyz="-0.15 0 -0.1" rpy="0 0 0"/>
    <parent link="body"/>
    <child link="caster_forward"/>
	</joint>

	<joint name="caster_backward_joint" type="fixed">
    <origin xyz="0.15 0 -0.1" rpy="0 0 0"/>
    <parent link="body"/>
    <child link="caster_backward"/>
	</joint>

	<joint name="lidar_base_joint" type="fixed">
    <origin xyz="0.0 0.0 0.125" rpy="0 0 0"/>
    <parent link="body"/>
    <child link="lidar_base"/>
	</joint>

	<joint name="lidar_joint" type="fixed">
    <origin xyz="0.0 0.0 0.2" rpy="0 0 0"/>
    <parent link="body"/>
    <child link="lidar_link"/>
	</joint>


<!-- ################# Gazebo上の設定 ################## -->
	<!-- 各パーツの情報を設定 -->
	<gazebo reference="body">
		<mu1>0.2</mu1>
		<mu2>0.2</mu2>
		<material>Gazebo/Red</material>
	</gazebo>

	<gazebo reference="wheel_left">
		<mu1>0.2</mu1>
		<mu2>0.2</mu2>
		<material>Gazebo/Blue</material>
	</gazebo>

	<gazebo reference="wheel_right">
		<mu1>0.2</mu1>
		<mu2>0.2</mu2>
		<material>Gazebo/Blue</material>
	</gazebo>

	<gazebo reference="caster_forward">
		<mu1>0.0</mu1>
		<mu2>0.0</mu2>
		<material>Gazebo/Green</material>
	</gazebo>

	<gazebo reference="caster_backward">
		<mu1>0.0</mu1>
		<mu2>0.0</mu2>
		<material>Gazebo/Black</material>
	</gazebo>
  
	<gazebo reference="lidar_base">
		<mu1>0.0</mu1>
		<mu2>0.0</mu2>
		<material>Gazebo/Yellow</material>
	</gazebo>

	<gazebo reference="lidar_link">
		<mu1>0.0</mu1>
		<mu2>0.0</mu2>
		<material>Gazebo/Purple</material>
	</gazebo>

<!--差動駆動プラグインをロードするための追加要素-->
  <gazebo>
    <!--差動駆動プラグインを指定-->
    <plugin name="differential_drive_controller" filename="libgazebo_ros_diff_drive.so">
      <!--left_wheel_jointとright_wheel_jointをそれぞれ左関節右関節に指定-->
      <leftJoint>wheel_left_joint</leftJoint>
      <rightJoint>wheel_right_joint</rightJoint>
      <!--台座であるbase_linkをrobotBaseFrameに指定-->
      <robotBaseFrame>base_link</robotBaseFrame>
      <!--トレッドを0.25m，車輪直径0.07mとする-->
      <wheelSeparation>0.45</wheelSeparation>
      <wheelDiameter>0.15</wheelDiameter>
      <!--車輪の状態を配信する設定にする-->
      <publishWheelJointState>true</publishWheelJointState>
    </plugin>
  </gazebo>


  <!-- Lidar(ydlidarを例にパラメータを設定) -->
  <!-- GPU rayというタイプで作成 -->
  <gazebo reference="lidar_link">
    <sensor type="gpu_ray" name="head_ydlidar_sensor">
      <pose>0 0 0 0 0 0</pose>
      <visualize>true</visualize>
      <update_rate>40</update_rate>
      <ray>
        <scan>
          <horizontal>
            <samples>700</samples>
            <resolution>1</resolution>
            <min_angle>-3.14159265358979</min_angle>
            <max_angle>3.14159265358979</max_angle>
          </horizontal>
        </scan>
        <range>
          <min>0.12</min>
          <max>8</max>
          <resolution>0.72</resolution>
        </range>
        <noise>
          <type>gaussian</type>
          <!-- Noise parameters based on published spec for Hokuyo laser
               achieving "+-30mm" accuracy at range < 10m.  A mean of 0.0m and
               stddev of 0.01m will put 99.7% of samples within 0.03m of the true
               reading. -->
          <mean>0.0</mean>
          <stddev>0.01</stddev>
        </noise>
      </ray>
      <plugin name="gazebo_ros_head_ydlidar_controller" filename="libgazebo_ros_gpu_laser.so">
        <topicName>/scan</topicName>
        <frameName>lidar_link</frameName>
      </plugin>
    </sensor>
  </gazebo>

</robot>
