<sdf version='1.7'>
  <model name='sobit_mini'>
    <link name='base_footprint'>
      <inertial>
        <pose>0.04213 -0.020697 0.155208 0 -0 0</pose>
        <mass>6.7613</mass>
        <inertia>
          <ixx>2.13949</ixx>
          <ixy>-0.00780862</ixy>
          <ixz>-0.00394758</ixz>
          <iyy>2.17369</iyy>
          <iyz>0.0167507</iyz>
          <izz>2.12254</izz>
        </inertia>
      </inertial>
      <collision name='base_footprint_fixed_joint_lump__base_collision'>
        <pose>0 0 0.06969 0 -0 0</pose>
        <geometry>
          <cylinder>
            <length>0.10938</length>
            <radius>0.178</radius>
          </cylinder>
        </geometry>
      </collision>
      <collision name='base_footprint_fixed_joint_lump__caster_back_link_collision_1'>
        <pose>-0.135 0 0.0192 -1.5708 0 0</pose>
        <geometry>
          <cylinder>
            <length>0.0176</length>
            <radius>0.017</radius>
          </cylinder>
        </geometry>
      </collision>
      <collision name='base_footprint_fixed_joint_lump__caster_front_link_collision_2'>
        <pose>0.115 0 0.0172 -1.5708 0 0</pose>
        <geometry>
          <cylinder>
            <length>0.0176</length>
            <radius>0.017</radius>
          </cylinder>
        </geometry>
      </collision>
      <collision name='base_footprint_fixed_joint_lump__plate_bottom_link_collision_3'>
        <pose>0 0 0.1408 0 -0 0</pose>
        <geometry>
          <cylinder>
            <length>0.006</length>
            <radius>0.17</radius>
          </cylinder>
        </geometry>
      </collision>
      <collision name='base_footprint_fixed_joint_lump__lidar_base_link_collision_4'>
        <pose>0.217724 0 0.1493 0 0 -1.5708</pose>
        <geometry>
          <mesh>
            <scale>1 1 1</scale>
            <uri>model://sobit_mini_description/meshes/sobit_mini_urg_sup.dae</uri>
          </mesh>
        </geometry>
      </collision>
      <collision name='base_footprint_fixed_joint_lump__plate_middle_link_collision_5'>
        <pose>0 0 0.2748 0 -0 0</pose>
        <geometry>
          <cylinder>
            <length>0.006</length>
            <radius>0.17</radius>
          </cylinder>
        </geometry>
      </collision>
      <collision name='base_footprint_fixed_joint_lump__body_big_gear_base_link_collision_6'>
        <pose>-0.01364 0 0.2779 0 -0 0</pose>
        <geometry>
          <mesh>
            <scale>1 1 1</scale>
            <uri>model://sobit_mini_description/meshes/body/sobit_mini_small_gear.stl</uri>
          </mesh>
        </geometry>
      </collision>
      <collision name='base_footprint_fixed_joint_lump__body_small_gear_link_collision_7'>
        <pose>-0.01364 -0.14 0.2748 -0 0 -1.5708</pose>
        <geometry>
          <mesh>
            <scale>1 1 1</scale>
            <uri>model://sobit_mini_description/meshes/body/sobit_mini_small_gear.stl</uri>
          </mesh>
        </geometry>
      </collision>
      <visual name='base_footprint_fixed_joint_lump__base_link_visual'>
        <pose>0.001 0 0.06219 0 -0 0</pose>
        <geometry>
          <mesh>
            <scale>1 1 1</scale>
            <uri>model://kobuki_description/meshes/main_body.dae</uri>
          </mesh>
        </geometry>
      </visual>
      <visual name='base_footprint_fixed_joint_lump__plate_bottom_link_visual_1'>
        <pose>0.02364 0 0.1408 0 -0 0</pose>
        <geometry>
          <mesh>
            <scale>1 1 1</scale>
            <uri>model://turtlebot_description/meshes/stacks/hexagons/plate_bottom.dae</uri>
          </mesh>
        </geometry>
      </visual>
      <visual name='base_footprint_fixed_joint_lump__lidar_base_link_visual_2'>
        <pose>0.217724 0 0.1493 0 0 -1.5708</pose>
        <geometry>
          <mesh>
            <scale>1 1 1</scale>
            <uri>model://sobit_mini_description/meshes/sobit_mini_urg_sup.dae</uri>
          </mesh>
        </geometry>
      </visual>
      <visual name='base_footprint_fixed_joint_lump__lidar_laser_mount_visual_3'>
        <pose>0.217724 0 0.1493 0 -0 0</pose>
        <geometry>
          <mesh>
            <scale>1 1 1</scale>
            <uri>model://urg_node/meshes/hokuyo_ust10_20.stl</uri>
          </mesh>
        </geometry>
      </visual>
      <visual name='base_footprint_fixed_joint_lump__plate_middle_link_visual_4'>
        <pose>-0.01364 0 0.2748 0 -0 0</pose>
        <geometry>
          <mesh>
            <scale>1 1 1</scale>
            <uri>model://turtlebot_description/meshes/stacks/hexagons/plate_top.dae</uri>
          </mesh>
        </geometry>
      </visual>
      <visual name='base_footprint_fixed_joint_lump__body_big_gear_base_link_visual_5'>
        <pose>-0.01364 0 0.2779 0 -0 0</pose>
        <geometry>
          <mesh>
            <scale>1 1 1</scale>
            <uri>model://sobit_mini_description/meshes/body/big_gear_base.stl</uri>
          </mesh>
        </geometry>
      </visual>
      <visual name='base_footprint_fixed_joint_lump__body_small_gear_link_visual_6'>
        <pose>-0.01364 -0.14 0.2748 -0 0 -1.5708</pose>
        <geometry>
          <mesh>
            <scale>1 1 1</scale>
            <uri>model://sobit_mini_description/meshes/body/sobit_mini_small_gear.stl</uri>
          </mesh>
        </geometry>
      </visual>
      <gravity>0</gravity>
      <sensor name='lidar_laser' type='ray'>
        <visualize>0</visualize>
        <update_rate>50</update_rate>
        <ray>
          <scan>
            <horizontal>
              <samples>720</samples>
              <resolution>1</resolution>
              <min_angle>-2.35619</min_angle>
              <max_angle>2.35619</max_angle>
            </horizontal>
          </scan>
          <range>
            <min>0.1</min>
            <max>60</max>
            <resolution>0.01</resolution>
          </range>
          <noise>
            <type>gaussian</type>
            <mean>0</mean>
            <stddev>0.001</stddev>
          </noise>
        </ray>
        <plugin name='gazebo_ros_laser' filename='libgazebo_ros_laser.so'>
          <topicName>scan</topicName>
          <frameName>lidar_laser</frameName>
        </plugin>
        <pose>0.217724 0 0.1967 0 -0 0</pose>
      </sensor>
    </link>
    <joint name='body_roll_joint' type='revolute'>
      <pose relative_to='base_footprint'>-0.01364 0 0.3104 0 -0 0</pose>
      <parent>base_footprint</parent>
      <child>body_roll_link</child>
      <axis>
        <xyz>0 0 1</xyz>
        <limit>
          <lower>-1.5708</lower>
          <upper>1.5708</upper>
          <effort>30</effort>
          <velocity>1.5708</velocity>
        </limit>
        <dynamics>
          <spring_reference>0</spring_reference>
          <spring_stiffness>0</spring_stiffness>
        </dynamics>
      </axis>
    </joint>
    <link name='body_roll_link'>
      <pose relative_to='body_roll_joint'>0 0 0 0 -0 0</pose>
      <inertial>
        <pose>-0.002404 0 0.028543 0 -0 0</pose>
        <mass>4.16</mass>
        <inertia>
          <ixx>6.02265</ixx>
          <ixy>0</ixy>
          <ixz>0.000294572</ixz>
          <iyy>6.02273</iyy>
          <iyz>0</iyz>
          <izz>6.00008</izz>
        </inertia>
      </inertial>
      <collision name='body_roll_link_collision'>
        <pose>0 0 0 0 -0 0</pose>
        <geometry>
          <mesh>
            <scale>1 1 1</scale>
            <uri>model://sobit_mini_description/meshes/body/sobit_mini_big_gear.stl</uri>
          </mesh>
        </geometry>
      </collision>
      <collision name='body_roll_link_fixed_joint_lump__body_back_pole_link_collision_1'>
        <pose>-0.01 0 0.058 0 -0 1.5708</pose>
        <geometry>
          <mesh>
            <scale>1 1 1</scale>
            <uri>model://sobit_mini_description/meshes/body/sobit_mini_center_back.stl</uri>
          </mesh>
        </geometry>
      </collision>
      <collision name='body_roll_link_fixed_joint_lump__body_front_pole_link_collision_2'>
        <pose>0 0 0.0005 0 -0 1.5708</pose>
        <geometry>
          <mesh>
            <scale>1 1 1</scale>
            <uri>model://sobit_mini_description/meshes/body/spine.stl</uri>
          </mesh>
        </geometry>
      </collision>
      <collision name='body_roll_link_fixed_joint_lump__l_arm_shoulder_fixed_link_collision_3'>
        <pose>0 0 0.376488 0 -0 1.5708</pose>
        <geometry>
          <mesh>
            <scale>1 1 1</scale>
            <uri>model://sobit_mini_description/meshes/L_arm/L_ARM_SHOULDER_ROLL_JOINT.stl</uri>
          </mesh>
        </geometry>
      </collision>
      <collision name='body_roll_link_fixed_joint_lump__r_arm_shoulder_fixed_link_collision_4'>
        <pose>0 0 0.376488 0 -0 1.5708</pose>
        <geometry>
          <mesh>
            <scale>1 1 1</scale>
            <uri>model://sobit_mini_description/meshes/R_arm/R_ARM_SHOULDER_ROLL_JOINT.stl</uri>
          </mesh>
        </geometry>
      </collision>
      <collision name='body_roll_link_fixed_joint_lump__body_sobit_mini_cover_collision_5'>
        <pose>0 0 0.459 0 -0 1.5708</pose>
        <geometry>
          <mesh>
            <scale>1 1 1</scale>
            <uri>model://sobit_mini_description/meshes/body/sobit_mini_body_cover.dae</uri>
          </mesh>
        </geometry>
      </collision>
      <visual name='body_roll_link_visual'>
        <pose>0 0 0 0 -0 0</pose>
        <geometry>
          <mesh>
            <scale>1 1 1</scale>
            <uri>model://sobit_mini_description/meshes/body/sobit_mini_big_gear.stl</uri>
          </mesh>
        </geometry>
      </visual>
      <visual name='body_roll_link_fixed_joint_lump__body_back_pole_link_visual_1'>
        <pose>-0.01 0 0.058 0 -0 1.5708</pose>
        <geometry>
          <mesh>
            <scale>1 1 1</scale>
            <uri>model://sobit_mini_description/meshes/body/sobit_mini_center_back.stl</uri>
          </mesh>
        </geometry>
      </visual>
      <visual name='body_roll_link_fixed_joint_lump__body_front_pole_link_visual_2'>
        <pose>0 0 0.0005 0 -0 1.5708</pose>
        <geometry>
          <mesh>
            <scale>1 1 1</scale>
            <uri>model://sobit_mini_description/meshes/body/spine.stl</uri>
          </mesh>
        </geometry>
      </visual>
      <visual name='body_roll_link_fixed_joint_lump__l_arm_shoulder_fixed_link_visual_3'>
        <pose>0 0 0.376488 0 -0 1.5708</pose>
        <geometry>
          <mesh>
            <scale>1 1 1</scale>
            <uri>model://sobit_mini_description/meshes/L_arm/L_ARM_SHOULDER_ROLL_JOINT.stl</uri>
          </mesh>
        </geometry>
      </visual>
      <visual name='body_roll_link_fixed_joint_lump__r_arm_shoulder_fixed_link_visual_4'>
        <pose>0 0 0.376488 0 -0 1.5708</pose>
        <geometry>
          <mesh>
            <scale>1 1 1</scale>
            <uri>model://sobit_mini_description/meshes/R_arm/R_ARM_SHOULDER_ROLL_JOINT.stl</uri>
          </mesh>
        </geometry>
      </visual>
      <visual name='body_roll_link_fixed_joint_lump__body_sobit_mini_cover_visual_5'>
        <pose>0 0 0.459 0 -0 1.5708</pose>
        <geometry>
          <mesh>
            <scale>1 1 1</scale>
            <uri>model://sobit_mini_description/meshes/body/sobit_mini_body_cover.dae</uri>
          </mesh>
        </geometry>
      </visual>
    </link>
    <joint name='head_pan_joint' type='revolute'>
      <pose relative_to='body_roll_link'>0 0 0.5165 0 -0 0</pose>
      <parent>body_roll_link</parent>
      <child>head_pan_link</child>
      <axis>
        <xyz>0 0 1</xyz>
        <limit>
          <lower>-2.617</lower>
          <upper>2.617</upper>
          <effort>30</effort>
          <velocity>1.5708</velocity>
        </limit>
        <dynamics>
          <spring_reference>0</spring_reference>
          <spring_stiffness>0</spring_stiffness>
        </dynamics>
      </axis>
    </joint>
    <link name='head_pan_link'>
      <pose relative_to='head_pan_joint'>0 0 0 0 -0 0</pose>
      <inertial>
        <pose>0 0 0.0135 1.5708 -0 0</pose>
        <mass>0.6</mass>
        <inertia>
          <ixx>1</ixx>
          <ixy>0</ixy>
          <ixz>0</ixz>
          <iyy>1</iyy>
          <iyz>0</iyz>
          <izz>1</izz>
        </inertia>
      </inertial>
      <collision name='head_pan_link_collision'>
        <pose>0 0 0 0 -0 1.5708</pose>
        <geometry>
          <mesh>
            <scale>1 1 1</scale>
            <uri>model://sobit_mini_description/meshes/head/HEAD_PAN_JOINT.stl</uri>
          </mesh>
        </geometry>
      </collision>
      <visual name='head_pan_link_visual'>
        <pose>0 0 0 0 -0 1.5708</pose>
        <geometry>
          <mesh>
            <scale>1 1 1</scale>
            <uri>model://sobit_mini_description/meshes/head/HEAD_PAN_JOINT.stl</uri>
          </mesh>
        </geometry>
      </visual>
    </link>
    <joint name='head_tilt_joint' type='revolute'>
      <pose relative_to='head_pan_link'>0 0 0.017 0 -0 0</pose>
      <parent>head_pan_link</parent>
      <child>head_tilt_link</child>
      <axis>
        <xyz>0 -1 0</xyz>
        <limit>
          <lower>-1</lower>
          <upper>1</upper>
          <effort>30</effort>
          <velocity>1.5708</velocity>
        </limit>
        <dynamics>
          <spring_reference>0</spring_reference>
          <spring_stiffness>0</spring_stiffness>
        </dynamics>
      </axis>
    </joint>
    <link name='head_tilt_link'>
      <pose relative_to='head_tilt_joint'>0 0 0 0 -0 0</pose>
      <inertial>
        <pose>-0.028063 0.000918 0.126436 1.5708 -0 0</pose>
        <mass>1.372</mass>
        <inertia>
          <ixx>2.01343</ixx>
          <ixy>0.00165042</ixy>
          <ixz>5.43848e-05</ixz>
          <iyy>2.0044</iyy>
          <iyz>7.0206e-05</iyz>
          <izz>2.01053</izz>
        </inertia>
      </inertial>
      <collision name='head_tilt_link_collision'>
        <pose>0 0 0 0 -0 1.5708</pose>
        <geometry>
          <mesh>
            <scale>1 1 1</scale>
            <uri>model://sobit_mini_description/meshes/head/HEAD_TILT_JOINT.dae</uri>
          </mesh>
        </geometry>
      </collision>
      <collision name='head_tilt_link_fixed_joint_lump__head_camera_link_collision_1'>
        <pose>0.0151 0 0.182155 0 -0 0</pose>
        <geometry>
          <box>
            <size>0.02505 0.09 0.025</size>
          </box>
        </geometry>
      </collision>
      <collision name='head_tilt_link_fixed_joint_lump__mic_base_link_collision_2'>
        <pose>-0.039589 0 0.169655 0 -0 0</pose>
        <geometry>
          <mesh>
            <scale>1 1 1</scale>
            <uri>model://sobit_mini_description/meshes/sensor/mic.stl</uri>
          </mesh>
        </geometry>
      </collision>
      <visual name='head_tilt_link_visual'>
        <pose>0 0 0 0 -0 1.5708</pose>
        <geometry>
          <mesh>
            <scale>1 1 1</scale>
            <uri>model://sobit_mini_description/meshes/head/HEAD_TILT_JOINT.dae</uri>
          </mesh>
        </geometry>
      </visual>
      <visual name='head_tilt_link_fixed_joint_lump__head_camera_link_visual_1'>
        <pose>0.0194 0 0.182155 1.5708 -0 1.5708</pose>
        <geometry>
          <mesh>
            <scale>1 1 1</scale>
            <uri>model://realsense2_description/meshes/d435.dae</uri>
          </mesh>
        </geometry>
      </visual>
      <visual name='head_tilt_link_fixed_joint_lump__mic_base_link_visual_2'>
        <pose>-0.039589 0 0.169655 0 -0 1.5708</pose>
        <geometry>
          <mesh>
            <scale>1 1 1</scale>
            <uri>model://sobit_mini_description/meshes/sensor/mic.stl</uri>
          </mesh>
        </geometry>
      </visual>
    </link>
    <joint name='l_arm_shoulder_roll_joint' type='revolute'>
      <pose relative_to='body_roll_link'>0 0.1415 0.391649 0 -0 0</pose>
      <parent>body_roll_link</parent>
      <child>l_arm_shoulder_roll_link</child>
      <axis>
        <xyz>0 1 0</xyz>
        <limit>
          <lower>-3.14159</lower>
          <upper>1.5708</upper>
          <effort>30</effort>
          <velocity>3.14159</velocity>
        </limit>
        <dynamics>
          <spring_reference>0</spring_reference>
          <spring_stiffness>0</spring_stiffness>
        </dynamics>
      </axis>
    </joint>
    <link name='l_arm_shoulder_roll_link'>
      <pose relative_to='l_arm_shoulder_roll_joint'>0 0 0 0 -0 0</pose>
      <inertial>
        <pose>0 0 0 0 -0 0</pose>
        <mass>0.08</mass>
        <inertia>
          <ixx>1</ixx>
          <ixy>0</ixy>
          <ixz>0</ixz>
          <iyy>1</iyy>
          <iyz>0</iyz>
          <izz>1</izz>
        </inertia>
      </inertial>
      <collision name='l_arm_shoulder_roll_link_collision'>
        <pose>0 0 0 0 -0 1.5708</pose>
        <geometry>
          <mesh>
            <scale>1 1 1</scale>
            <uri>model://sobit_mini_description/meshes/L_arm/L_ARM_SHOULDER_FLEX_JOINT.stl</uri>
          </mesh>
        </geometry>
      </collision>
      <visual name='l_arm_shoulder_roll_link_visual'>
        <pose>0 0 0 0 -0 1.5708</pose>
        <geometry>
          <mesh>
            <scale>1 1 1</scale>
            <uri>model://sobit_mini_description/meshes/L_arm/L_ARM_SHOULDER_FLEX_JOINT.stl</uri>
          </mesh>
        </geometry>
      </visual>
    </link>
    <joint name='l_arm_shoulder_pan_joint' type='revolute'>
      <pose relative_to='l_arm_shoulder_roll_link'>0 0.05375 0 0 -0 0</pose>
      <parent>l_arm_shoulder_roll_link</parent>
      <child>l_arm_shoulder_pan_link</child>
      <axis>
        <xyz>1 0 0</xyz>
        <limit>
          <lower>-1.5708</lower>
          <upper>1.5708</upper>
          <effort>30</effort>
          <velocity>1.5708</velocity>
        </limit>
        <dynamics>
          <spring_reference>0</spring_reference>
          <spring_stiffness>0</spring_stiffness>
        </dynamics>
      </axis>
    </joint>
    <link name='l_arm_shoulder_pan_link'>
      <pose relative_to='l_arm_shoulder_pan_joint'>0 0 0 0 -0 0</pose>
      <inertial>
        <pose>0 0 0 0 -0 0</pose>
        <mass>0.08</mass>
        <inertia>
          <ixx>1</ixx>
          <ixy>0</ixy>
          <ixz>0</ixz>
          <iyy>1</iyy>
          <iyz>0</iyz>
          <izz>1</izz>
        </inertia>
      </inertial>
      <collision name='l_arm_shoulder_pan_link_collision'>
        <pose>0 0 0 0 -0 1.5708</pose>
        <geometry>
          <mesh>
            <scale>1 1 1</scale>
            <uri>model://sobit_mini_description/meshes/L_arm/L_ARM_ELBOW_TILT_JOINT.stl</uri>
          </mesh>
        </geometry>
      </collision>
      <visual name='l_arm_shoulder_pan_link_visual'>
        <pose>0 0 0 0 -0 1.5708</pose>
        <geometry>
          <mesh>
            <scale>1 1 1</scale>
            <uri>model://sobit_mini_description/meshes/L_arm/L_ARM_ELBOW_TILT_JOINT.stl</uri>
          </mesh>
        </geometry>
      </visual>
    </link>
    <joint name='l_arm_elbow_tilt_joint' type='revolute'>
      <pose relative_to='l_arm_shoulder_pan_link'>0 0.11125 0 0 -0 0</pose>
      <parent>l_arm_shoulder_pan_link</parent>
      <child>l_arm_elbow_tilt_link</child>
      <axis>
        <xyz>0 0 1</xyz>
        <limit>
          <lower>-1.5708</lower>
          <upper>0</upper>
          <effort>30</effort>
          <velocity>1.5708</velocity>
        </limit>
        <dynamics>
          <spring_reference>0</spring_reference>
          <spring_stiffness>0</spring_stiffness>
        </dynamics>
      </axis>
    </joint>
    <link name='l_arm_elbow_tilt_link'>
      <pose relative_to='l_arm_elbow_tilt_joint'>0 0 0 0 -0 0</pose>
      <inertial>
        <pose>0 0 0 0 -0 0</pose>
        <mass>0.08</mass>
        <inertia>
          <ixx>1</ixx>
          <ixy>0</ixy>
          <ixz>0</ixz>
          <iyy>1</iyy>
          <iyz>0</iyz>
          <izz>1</izz>
        </inertia>
      </inertial>
      <collision name='l_arm_elbow_tilt_link_collision'>
        <pose>0 0 0 0 -0 1.5708</pose>
        <geometry>
          <mesh>
            <scale>1 1 1</scale>
            <uri>model://sobit_mini_description/meshes/L_arm/L_ARM_WRIST_TILT_JOINT.stl</uri>
          </mesh>
        </geometry>
      </collision>
      <visual name='l_arm_elbow_tilt_link_visual'>
        <pose>0 0 0 0 -0 1.5708</pose>
        <geometry>
          <mesh>
            <scale>1 1 1</scale>
            <uri>model://sobit_mini_description/meshes/L_arm/L_ARM_WRIST_TILT_JOINT.stl</uri>
          </mesh>
        </geometry>
      </visual>
    </link>
    <joint name='l_arm_wrist_tilt_joint' type='revolute'>
      <pose relative_to='l_arm_elbow_tilt_link'>0 0.10275 0 0 -0 0</pose>
      <parent>l_arm_elbow_tilt_link</parent>
      <child>l_arm_wrist_tilt_link</child>
      <axis>
        <xyz>0 0 1</xyz>
        <limit>
          <lower>-1.5708</lower>
          <upper>1.5708</upper>
          <effort>30</effort>
          <velocity>1.5708</velocity>
        </limit>
        <dynamics>
          <spring_reference>0</spring_reference>
          <spring_stiffness>0</spring_stiffness>
        </dynamics>
      </axis>
    </joint>
    <link name='l_arm_wrist_tilt_link'>
      <pose relative_to='l_arm_wrist_tilt_joint'>0 0 0 0 -0 0</pose>
      <inertial>
        <pose>0 0 0 0 -0 0</pose>
        <mass>0.08</mass>
        <inertia>
          <ixx>1</ixx>
          <ixy>0</ixy>
          <ixz>0</ixz>
          <iyy>1</iyy>
          <iyz>0</iyz>
          <izz>1</izz>
        </inertia>
      </inertial>
      <collision name='l_arm_wrist_tilt_link_collision'>
        <pose>0 0 0 3.14159 -1.5708 0</pose>
        <geometry>
          <mesh>
            <scale>1 1 1</scale>
            <uri>model://sobit_mini_description/meshes/L_hand/L_hand_JOINT.stl</uri>
          </mesh>
        </geometry>
      </collision>
      <visual name='l_arm_wrist_tilt_link_visual'>
        <pose>0 0 0 3.14159 -1.5708 0</pose>
        <geometry>
          <mesh>
            <scale>1 1 1</scale>
            <uri>model://sobit_mini_description/meshes/L_hand/L_hand_JOINT.stl</uri>
          </mesh>
        </geometry>
      </visual>
    </link>
    <joint name='r_arm_shoulder_roll_joint' type='revolute'>
      <pose relative_to='body_roll_link'>0 -0.1415 0.391649 0 -0 0</pose>
      <parent>body_roll_link</parent>
      <child>r_arm_shoulder_roll_link</child>
      <axis>
        <xyz>0 -1 0</xyz>
        <limit>
          <lower>-1.5708</lower>
          <upper>3.14159</upper>
          <effort>30</effort>
          <velocity>1.5708</velocity>
        </limit>
        <dynamics>
          <spring_reference>0</spring_reference>
          <spring_stiffness>0</spring_stiffness>
        </dynamics>
      </axis>
    </joint>
    <link name='r_arm_shoulder_roll_link'>
      <pose relative_to='r_arm_shoulder_roll_joint'>0 0 0 0 -0 0</pose>
      <inertial>
        <pose>0 0 0 0 -0 0</pose>
        <mass>0.08</mass>
        <inertia>
          <ixx>1</ixx>
          <ixy>0</ixy>
          <ixz>0</ixz>
          <iyy>1</iyy>
          <iyz>0</iyz>
          <izz>1</izz>
        </inertia>
      </inertial>
      <collision name='r_arm_shoulder_roll_link_collision'>
        <pose>0 0 0 0 -0 1.5708</pose>
        <geometry>
          <mesh>
            <scale>1 1 1</scale>
            <uri>model://sobit_mini_description/meshes/R_arm/R_ARM_SHOULDER_FLEX_JOINT.stl</uri>
          </mesh>
        </geometry>
      </collision>
      <visual name='r_arm_shoulder_roll_link_visual'>
        <pose>0 0 0 0 -0 1.5708</pose>
        <geometry>
          <mesh>
            <scale>1 1 1</scale>
            <uri>model://sobit_mini_description/meshes/R_arm/R_ARM_SHOULDER_FLEX_JOINT.stl</uri>
          </mesh>
        </geometry>
      </visual>
    </link>
    <joint name='r_arm_shoulder_pan_joint' type='revolute'>
      <pose relative_to='r_arm_shoulder_roll_link'>0 -0.05375 0 0 -0 0</pose>
      <parent>r_arm_shoulder_roll_link</parent>
      <child>r_arm_shoulder_pan_link</child>
      <axis>
        <xyz>1 0 0</xyz>
        <limit>
          <lower>-1.5708</lower>
          <upper>1.5708</upper>
          <effort>30</effort>
          <velocity>1.5708</velocity>
        </limit>
        <dynamics>
          <spring_reference>0</spring_reference>
          <spring_stiffness>0</spring_stiffness>
        </dynamics>
      </axis>
    </joint>
    <link name='r_arm_shoulder_pan_link'>
      <pose relative_to='r_arm_shoulder_pan_joint'>0 0 0 0 -0 0</pose>
      <inertial>
        <pose>0 0 0 0 -0 0</pose>
        <mass>0.08</mass>
        <inertia>
          <ixx>1</ixx>
          <ixy>0</ixy>
          <ixz>0</ixz>
          <iyy>1</iyy>
          <iyz>0</iyz>
          <izz>1</izz>
        </inertia>
      </inertial>
      <collision name='r_arm_shoulder_pan_link_collision'>
        <pose>0 0 0 1.5708 -0 1.5708</pose>
        <geometry>
          <mesh>
            <scale>1 1 1</scale>
            <uri>model://sobit_mini_description/meshes/R_arm/R_ARM_ELBOW_TILT_JOINT.stl</uri>
          </mesh>
        </geometry>
      </collision>
      <visual name='r_arm_shoulder_pan_link_visual'>
        <pose>0 0 0 1.5708 -0 1.5708</pose>
        <geometry>
          <mesh>
            <scale>1 1 1</scale>
            <uri>model://sobit_mini_description/meshes/R_arm/R_ARM_ELBOW_TILT_JOINT.stl</uri>
          </mesh>
        </geometry>
      </visual>
    </link>
    <joint name='r_arm_elbow_tilt_joint' type='revolute'>
      <pose relative_to='r_arm_shoulder_pan_link'>0 -0.11125 0 0 -0 0</pose>
      <parent>r_arm_shoulder_pan_link</parent>
      <child>r_arm_elbow_tilt_link</child>
      <axis>
        <xyz>0 0 1</xyz>
        <limit>
          <lower>0</lower>
          <upper>1.5708</upper>
          <effort>30</effort>
          <velocity>1.5708</velocity>
        </limit>
        <dynamics>
          <spring_reference>0</spring_reference>
          <spring_stiffness>0</spring_stiffness>
        </dynamics>
      </axis>
    </joint>
    <link name='r_arm_elbow_tilt_link'>
      <pose relative_to='r_arm_elbow_tilt_joint'>0 0 0 0 -0 0</pose>
      <inertial>
        <pose>0 0 0 0 -0 0</pose>
        <mass>0.08</mass>
        <inertia>
          <ixx>1</ixx>
          <ixy>0</ixy>
          <ixz>0</ixz>
          <iyy>1</iyy>
          <iyz>0</iyz>
          <izz>1</izz>
        </inertia>
      </inertial>
      <collision name='r_arm_elbow_tilt_link_collision'>
        <pose>0 0 0 0 -0 1.5708</pose>
        <geometry>
          <mesh>
            <scale>1 1 1</scale>
            <uri>model://sobit_mini_description/meshes/R_arm/R_ARM_WRIST_TILT_JOINT.stl</uri>
          </mesh>
        </geometry>
      </collision>
      <visual name='r_arm_elbow_tilt_link_visual'>
        <pose>0 0 0 0 -0 1.5708</pose>
        <geometry>
          <mesh>
            <scale>1 1 1</scale>
            <uri>model://sobit_mini_description/meshes/R_arm/R_ARM_WRIST_TILT_JOINT.stl</uri>
          </mesh>
        </geometry>
      </visual>
    </link>
    <joint name='r_arm_wrist_tilt_joint' type='revolute'>
      <pose relative_to='r_arm_elbow_tilt_link'>0 -0.10275 0 0 -0 0</pose>
      <parent>r_arm_elbow_tilt_link</parent>
      <child>r_arm_wrist_tilt_link</child>
      <axis>
        <xyz>0 0 1</xyz>
        <limit>
          <lower>-1.5708</lower>
          <upper>1.5708</upper>
          <effort>30</effort>
          <velocity>1.5708</velocity>
        </limit>
        <dynamics>
          <spring_reference>0</spring_reference>
          <spring_stiffness>0</spring_stiffness>
        </dynamics>
      </axis>
    </joint>
    <link name='r_arm_wrist_tilt_link'>
      <pose relative_to='r_arm_wrist_tilt_joint'>0 0 0 0 -0 0</pose>
      <inertial>
        <pose>0 0 0 0 -0 0</pose>
        <mass>0.08</mass>
        <inertia>
          <ixx>1</ixx>
          <ixy>0</ixy>
          <ixz>0</ixz>
          <iyy>1</iyy>
          <iyz>0</iyz>
          <izz>1</izz>
        </inertia>
      </inertial>
      <collision name='r_arm_wrist_tilt_link_collision'>
        <pose>0 0 0 0 1.5708 0</pose>
        <geometry>
          <mesh>
            <scale>1 1 1</scale>
            <uri>model://sobit_mini_description/meshes/R_hand/R_hand_JOINT.stl</uri>
          </mesh>
        </geometry>
      </collision>
      <visual name='r_arm_wrist_tilt_link_visual'>
        <pose>0 0 0 0 1.5708 0</pose>
        <geometry>
          <mesh>
            <scale>1 1 1</scale>
            <uri>model://sobit_mini_description/meshes/R_hand/R_hand_JOINT.stl</uri>
          </mesh>
        </geometry>
      </visual>
    </link>
    <joint name='wheel_l_joint' type='revolute'>
      <pose relative_to='base_footprint'>0 0.115 0.0352 -1.5708 0 0</pose>
      <parent>base_footprint</parent>
      <child>wheel_l_link</child>
      <axis>
        <xyz>0 0 1</xyz>
        <limit>
          <lower>-1e+16</lower>
          <upper>1e+16</upper>
        </limit>
        <dynamics>
          <spring_reference>0</spring_reference>
          <spring_stiffness>0</spring_stiffness>
        </dynamics>
      </axis>
    </joint>
    <link name='wheel_l_link'>
      <pose relative_to='wheel_l_joint'>0 0 0 0 -0 0</pose>
      <inertial>
        <pose>0 0 0 0 -0 0</pose>
        <mass>0.01</mass>
        <inertia>
          <ixx>0.001</ixx>
          <ixy>0</ixy>
          <ixz>0</ixz>
          <iyy>0.001</iyy>
          <iyz>0</iyz>
          <izz>0.001</izz>
        </inertia>
      </inertial>
      <collision name='wheel_l_link_collision'>
        <pose>0 0 0 0 -0 0</pose>
        <geometry>
          <cylinder>
            <length>0.0206</length>
            <radius>0.0352</radius>
          </cylinder>
        </geometry>
      </collision>
      <visual name='wheel_l_link_visual'>
        <pose>0 0 0 0 -0 0</pose>
        <geometry>
          <mesh>
            <scale>1 1 1</scale>
            <uri>model://kobuki_description/meshes/wheel.dae</uri>
          </mesh>
        </geometry>
      </visual>
    </link>
    <joint name='wheel_r_joint' type='revolute'>
      <pose relative_to='base_footprint'>0 -0.115 0.0352 -1.5708 0 0</pose>
      <parent>base_footprint</parent>
      <child>wheel_r_link</child>
      <axis>
        <xyz>0 0 1</xyz>
        <limit>
          <lower>-1e+16</lower>
          <upper>1e+16</upper>
        </limit>
        <dynamics>
          <spring_reference>0</spring_reference>
          <spring_stiffness>0</spring_stiffness>
        </dynamics>
      </axis>
    </joint>
    <link name='wheel_r_link'>
      <pose relative_to='wheel_r_joint'>0 0 0 0 -0 0</pose>
      <inertial>
        <pose>0 0 0 0 -0 0</pose>
        <mass>0.01</mass>
        <inertia>
          <ixx>0.001</ixx>
          <ixy>0</ixy>
          <ixz>0</ixz>
          <iyy>0.001</iyy>
          <iyz>0</iyz>
          <izz>0.001</izz>
        </inertia>
      </inertial>
      <collision name='wheel_r_link_collision'>
        <pose>0 0 0 0 -0 0</pose>
        <geometry>
          <cylinder>
            <length>0.0206</length>
            <radius>0.035</radius>
          </cylinder>
        </geometry>
      </collision>
      <visual name='wheel_r_link_visual'>
        <pose>0 0 0 0 -0 0</pose>
        <geometry>
          <mesh>
            <scale>1 1 1</scale>
            <uri>model://kobuki_description/meshes/wheel.dae</uri>
          </mesh>
        </geometry>
      </visual>
    </link>
  </model>
</sdf>
