<?xml version="1.0" ?>
<!-- =================================================================================== -->
<!-- |    This document was autogenerated by xacro from sobit_mini.urdf.xacro          | -->
<!-- |    EDITING THIS FILE BY HAND IS NOT RECOMMENDED                                 | -->
<!-- =================================================================================== -->
<robot name="sobit_mini" xmlns:controller="http://playerstage.sourceforge.net/gazebo/xmlschema/#controller" xmlns:interface="http://playerstage.sourceforge.net/gazebo/xmlschema/#interface" xmlns:sensor="http://playerstage.sourceforge.net/gazebo/xmlschema/#sensor">
  <material name="wheel">
    <color rgba="0.2 0.2 0.2 1.0"/>
  </material>
  <material name="black">
    <color rgba="0.1 0.1 0.1 1.0"/>
  </material>
  <material name="white">
    <color rgba="1.0 1.0 1.0 1.0"/>
  </material>
  <material name="silver">
    <color rgba="0.741 0.752 0.760 1.0"/>
  </material>
  <material name="red">
    <color rgba="1.0 0.0 0.0 1.0"/>
  </material>
  <material name="green">
    <color rgba="0.0 1.0 0.0 1.0"/>
  </material>
  <material name="blue">
    <color rgba="0.0 0.0 1.0 1.0"/>
  </material>
  <material name="dark_grey">
    <color rgba="0.175 0.175 0.175 1.0"/>
  </material>
  <material name="grey">
    <color rgba="0.3 0.3 0.3 1.0"/>
  </material>
  <material name="aluminum">
    <color rgba="0.5 0.5 0.5 1"/>
  </material>
  <material name="plastic">
    <color rgba="0.1 0.1 0.1 1"/>
  </material>
  <link name="base_footprint"/>
  <!--
       Base link is set at the bottom of the base mould.
       This is done to be compatible with the way base link
       was configured for turtlebot 1. Refer to
       https://github.com/turtlebot/turtlebot/issues/40
       To put the base link at the more oft used wheel
       axis, set the z-distance from the base_footprint
       to 0.352.
      -->
  <joint name="base_joint" type="fixed">
    <origin rpy="0 0 0" xyz="0 0 0.0102"/>
    <parent link="base_footprint"/>
    <child link="base_link"/>
  </joint>
  <link name="base_link">
    <visual>
      <geometry>
        <!-- new mesh -->
        <mesh filename="package://kobuki_description/meshes/main_body.dae"/>
      </geometry>
      <origin rpy="0 0 0" xyz="0.001 0 0.05199"/>
    </visual>
    <collision name="base">
      <geometry>
        <cylinder length="0.10938" radius="0.178"/>
      </geometry>
      <origin rpy="0 0 0" xyz="0.0 0 0.05949"/>
    </collision>
    <inertial>
      <!-- COM experimentally determined -->
      <origin xyz="0.01 0 0"/>
      <mass value="2.4"/>
      <!-- 2.4/2.6 kg for small/big battery pack -->
      <!-- Kobuki's inertia tensor is approximated by a cylinder with homogeneous mass distribution
             More details: http://en.wikipedia.org/wiki/List_of_moment_of_inertia_tensors
             m = 2.4 kg; h = 0.09 m; r = 0.175 m
             ixx = 1/12 * m * (3 * r^2 + h^2)
             iyy = 1/12 * m * (3 * r^2 + h^2)
             izz = 1/2 * m * r^2
          -->
      <inertia ixx="0.019995" ixy="0.0" ixz="0.0" iyy="0.019995" iyz="0.0" izz="0.03675"/>
    </inertial>
  </link>
  <joint name="wheel_l_joint" type="continuous">
    <parent link="base_link"/>
    <child link="wheel_l_link"/>
    <origin rpy="-1.5707963267948966 0 0" xyz="0.00 0.115 0.0250"/>
    <axis xyz="0 0 1"/>
  </joint>
  <link name="wheel_l_link">
    <visual>
      <geometry>
        <mesh filename="package://kobuki_description/meshes/wheel.dae"/>
      </geometry>
      <origin rpy="0 0 0" xyz="0 0 0"/>
    </visual>
    <collision>
      <geometry>
        <cylinder length="0.0206" radius="0.0352"/>
      </geometry>
      <origin rpy="0 0 0" xyz="0 0 0"/>
    </collision>
    <inertial>
      <mass value="0.01"/>
      <origin xyz="0 0 0"/>
      <inertia ixx="0.001" ixy="0.0" ixz="0.0" iyy="0.001" iyz="0.0" izz="0.001"/>
    </inertial>
  </link>
  <joint name="wheel_r_joint" type="continuous">
    <parent link="base_link"/>
    <child link="wheel_r_link"/>
    <origin rpy="-1.5707963267948966 0 0" xyz="0.00 -0.115 0.0250"/>
    <axis xyz="0 0 1"/>
  </joint>
  <link name="wheel_r_link">
    <visual>
      <geometry>
        <mesh filename="package://kobuki_description/meshes/wheel.dae"/>
      </geometry>
      <origin rpy="0 0 0" xyz="0 0 0"/>
    </visual>
    <collision>
      <geometry>
        <cylinder length="0.0206" radius="0.0350"/>
      </geometry>
      <origin rpy="0 0 0" xyz="0 0 0"/>
    </collision>
    <inertial>
      <mass value="0.01"/>
      <origin xyz="0 0 0"/>
      <inertia ixx="0.001" ixy="0.0" ixz="0.0" iyy="0.001" iyz="0.0" izz="0.001"/>
    </inertial>
  </link>
  <joint name="caster_front_joint" type="fixed">
    <parent link="base_link"/>
    <child link="caster_front_link"/>
    <origin rpy="-1.5707963267948966 0 0" xyz="0.115 0.0 0.007"/>
  </joint>
  <link name="caster_front_link">
    <collision>
      <geometry>
        <cylinder length="0.0176" radius="0.017"/>
      </geometry>
      <origin rpy="0 0 0" xyz="0 0 0"/>
    </collision>
    <inertial>
      <mass value="0.01"/>
      <origin xyz="0 0 0"/>
      <inertia ixx="0.001" ixy="0.0" ixz="0.0" iyy="0.001" iyz="0.0" izz="0.001"/>
    </inertial>
  </link>
  <joint name="caster_back_joint" type="fixed">
    <parent link="base_link"/>
    <child link="caster_back_link"/>
    <origin rpy="-1.5707963267948966 0 0" xyz="-0.135 0.0 0.009"/>
  </joint>
  <link name="caster_back_link">
    <collision>
      <geometry>
        <cylinder length="0.0176" radius="0.017"/>
      </geometry>
      <origin rpy="0 0 0" xyz="0 0 0"/>
    </collision>
    <inertial>
      <mass value="0.01"/>
      <origin xyz="0 0 0"/>
      <inertia ixx="0.001" ixy="0.0" ixz="0.0" iyy="0.001" iyz="0.0" izz="0.001"/>
    </inertial>
  </link>
  <!-- Kobuki's sensors -->
  <joint name="gyro_joint" type="fixed">
    <axis xyz="0 1 0"/>
    <origin rpy="0 0 0" xyz="0.056 0.062 0.0202"/>
    <parent link="base_link"/>
    <child link="gyro_link"/>
  </joint>
  <link name="gyro_link">
    <inertial>
      <mass value="0.001"/>
      <origin rpy="0 0 0" xyz="0 0 0"/>
      <inertia ixx="0.0001" ixy="0" ixz="0" iyy="0.000001" iyz="0" izz="0.0001"/>
    </inertial>
  </link>
  <joint name="cliff_sensor_left_joint" type="fixed">
    <origin rpy="0 1.5707963267948966 0" xyz="0.08734 0.13601 0.0214"/>
    <parent link="base_link"/>
    <child link="cliff_sensor_left_link"/>
  </joint>
  <link name="cliff_sensor_left_link">
    <inertial>
      <mass value="0.0001"/>
      <origin xyz="0 0 0"/>
      <inertia ixx="0.0001" ixy="0.0" ixz="0.0" iyy="0.0001" iyz="0.0" izz="0.0001"/>
    </inertial>
  </link>
  <joint name="cliff_sensor_right_joint" type="fixed">
    <origin rpy="0 1.5707963267948966 0" xyz="0.085 -0.13601 0.0214"/>
    <parent link="base_link"/>
    <child link="cliff_sensor_right_link"/>
  </joint>
  <link name="cliff_sensor_right_link">
    <inertial>
      <mass value="0.0001"/>
      <origin xyz="0 0 0"/>
      <inertia ixx="0.0001" ixy="0.0" ixz="0.0" iyy="0.0001" iyz="0.0" izz="0.0001"/>
    </inertial>
  </link>
  <joint name="cliff_sensor_front_joint" type="fixed">
    <origin rpy="0 1.5707963267948966 0" xyz="0.156 0.00 0.0214"/>
    <parent link="base_link"/>
    <child link="cliff_sensor_front_link"/>
  </joint>
  <link name="cliff_sensor_front_link">
    <inertial>
      <mass value="0.0001"/>
      <origin xyz="0 0 0"/>
      <inertia ixx="0.0001" ixy="0.0" ixz="0.0" iyy="0.0001" iyz="0.0" izz="0.0001"/>
    </inertial>
  </link>
  <stack_bottom_pole number="0" parent="base_link" x_loc="0.120" y_loc="0.082" z_loc="0.1028"/>
  <stack_bottom_pole number="1" parent="base_link" x_loc="0.055" y_loc="0.120" z_loc="0.1028"/>
  <stack_bottom_pole number="2" parent="base_link" x_loc="-0.055" y_loc="0.120" z_loc="0.1028"/>
  <stack_bottom_pole number="3" parent="base_link" x_loc="0.120" y_loc="-0.082" z_loc="0.1028"/>
  <stack_bottom_pole number="4" parent="base_link" x_loc="0.055" y_loc="-0.120" z_loc="0.1028"/>
  <stack_bottom_pole number="5" parent="base_link" x_loc="-0.055" y_loc="-0.120" z_loc="0.1028"/>
  <joint name="plate_bottom_joint" type="fixed">
    <origin rpy="0 0 0" xyz="0.02364 0.0 0.1306"/>
    <parent link="base_link"/>
    <child link="plate_bottom_link"/>
  </joint>
  <link name="plate_bottom_link">
    <visual>
      <origin rpy="0 0 0" xyz="0 0 0"/>
      <geometry>
        <mesh filename="package://turtlebot_description/meshes/stacks/hexagons/plate_bottom.dae"/>
      </geometry>
    </visual>
    <collision>
      <origin rpy="0 0 0" xyz="-0.02364 0 0"/>
      <geometry>
        <cylinder length="0.006" radius="0.170"/>
      </geometry>
    </collision>
    <inertial>
      <mass value="0.520"/>
      <origin xyz="0 0 0"/>
      <inertia ixx="0.003328" ixy="0.0" ixz="0.0" iyy="0.003328" iyz="0.0" izz="0.006656"/>
    </inertial>
  </link>
  <stack_3d_sensor_pole number="0" parent="base_link" x_loc="0.0381" y_loc="0.1505" z_loc="0.1735"/>
  <stack_3d_sensor_pole number="1" parent="base_link" x_loc="0.0381" y_loc="-0.1505" z_loc="0.1735"/>
  <stack_3d_sensor_pole number="2" parent="base_link" x_loc="-0.0381" y_loc="0.1505" z_loc="0.1735"/>
  <stack_3d_sensor_pole number="3" parent="base_link" x_loc="-0.0381" y_loc="-0.1505" z_loc="0.1735"/>
  <!-- <xacro:stack_middle_pole parent="${parent}" number="4" x_loc="0.0381" y_loc="0.1505" z_loc="0.13385" />
    <xacro:stack_middle_pole parent="${parent}" number="5" x_loc="0.0381" y_loc="-0.1505" z_loc="0.13385" />
    <xacro:stack_middle_pole parent="${parent}" number="6" x_loc="-0.0381" y_loc="0.1505" z_loc="0.13385" />
    <xacro:stack_middle_pole parent="${parent}" number="7" x_loc="-0.0381" y_loc="-0.1505" z_loc="0.13385" /> -->
  <joint name="plate_middle_joint" type="fixed">
    <!-- <origin xyz="-0.01364 0.0 0.222" rpy="0 0 0" /> -->
    <origin rpy="0 0 0" xyz="-0.01364 0.0 0.2646"/>
    <parent link="base_link"/>
    <child link="plate_middle_link"/>
  </joint>
  <link name="plate_middle_link">
    <visual>
      <origin rpy="0 0 0" xyz="0 0.0 0"/>
      <geometry>
        <mesh filename="package://turtlebot_description/meshes/stacks/hexagons/plate_top.dae"/>
      </geometry>
    </visual>
    <collision>
      <origin rpy="0 0 0" xyz="0.01364 0.0 0.0"/>
      <geometry>
        <cylinder length="0.006" radius="0.170"/>
      </geometry>
    </collision>
    <inertial>
      <mass value="0.520"/>
      <origin xyz="0 0 0"/>
      <inertia ixx="0.003328" ixy="0.0" ixz="0.0" iyy="0.003328" iyz="0.0" izz="0.006656"/>
    </inertial>
  </link>
  <joint name="lidar_base_joint" type="fixed">
    <origin rpy="0 0 0" xyz="0.194084 0.0 0.0085"/>
    <parent link="plate_bottom_link"/>
    <child link="lidar_base_link"/>
  </joint>
  <link name="lidar_base_link">
    <visual>
      <origin rpy="0.0 0.0 4.71238898038469" xyz="0.0 0.0 0.0"/>
      <geometry>
        <mesh filename="package://sobit_mini_description/meshes/sobit_mini_urg_sup.dae"/>
      </geometry>
    </visual>
    <collision>
      <origin rpy="0.0 0.0 4.71238898038469" xyz="0.0 0.0 0.0"/>
      <geometry>
        <mesh filename="package://sobit_mini_description/meshes/sobit_mini_urg_sup.dae"/>
      </geometry>
    </collision>
    <inertial>
      <origin rpy="0.0 0.0 0.0" xyz="0.0 0 0.0"/>
      <mass value="0.000001"/>
      <inertia ixx="0.0001" ixy="0.0" ixz="0.0" iyy="0.0001" iyz="0.0" izz="0.0001"/>
    </inertial>
  </link>
  <joint name="lidar_laser_mount_joint" type="fixed">
    <origin rpy="0.0 0.0 0.0" xyz="0.0 0.0 0.0"/>
    <parent link="lidar_base_link"/>
    <child link="lidar_laser_mount"/>
  </joint>
  <link name="lidar_laser_mount">
    <visual>
      <origin rpy="0 0 0" xyz="0 0 0"/>
      <geometry>
        <!-- Origin of this mesh is the base of the bracket. -->
        <mesh filename="package://urg_node/meshes/hokuyo_ust10_20.stl"/>
      </geometry>
      <material name="dark_grey"/>
    </visual>
  </link>
  <joint name="lidar_laser_joint" type="fixed">
    <!-- This offset is from the base of the bracket to the LIDAR's focal point. -->
    <origin rpy="0 0 0" xyz="0 0 0.0474"/>
    <parent link="lidar_laser_mount"/>
    <child link="lidar_laser"/>
  </joint>
  <link name="lidar_laser">
    <inertial>
      <mass value="1.3"/>
      <origin xyz="0 0 0"/>
      <inertia ixx="0.0036300318813199993" ixy="0.0" ixz="0.0" iyy="0.00369730685441" iyz="0.0" izz="0.0023214740714099995"/>
    </inertial>
  </link>
  <gazebo reference="lidar_laser">
    <turnGravityOff>true</turnGravityOff>
    <sensor name="lidar_laser" type="ray">
      <pose>0 0 0 0 0 0</pose>
      <visualize>false</visualize>
      <update_rate>50.0</update_rate>
      <ray>
        <scan>
          <horizontal>
            <samples>720</samples>
            <resolution>1</resolution>
            <min_angle>-2.35619</min_angle>
            <max_angle>2.35619</max_angle>
          </horizontal>
        </scan>
        <range>
          <min>0.1</min>
          <max>60.0</max>
          <resolution>0.01</resolution>
        </range>
        <noise>
          <type>gaussian</type>
          <mean>0.0</mean>
          <stddev>0.001</stddev>
        </noise>
      </ray>
      <plugin filename="libgazebo_ros_laser.so" name="gazebo_ros_laser">
        <topicName>scan</topicName>
        <frameName>lidar_laser</frameName>
        <!-- <robotNamespace>${robot_namespace}</robotNamespace> -->
      </plugin>
    </sensor>
  </gazebo>
  <!-- <gazebo reference="${prefix}_laser_mount">
      <material>Gazebo/DarkGrey</material>
    </gazebo> -->
  <joint name="body_small_gear_joint" type="fixed">
    <parent link="plate_middle_link"/>
    <child link="body_small_gear_link"/>
    <origin rpy="0 0 0" xyz="0.0 -0.14 0.0"/>
    <axis xyz="0 0 1"/>
  </joint>
  <link name="body_small_gear_link">
    <visual>
      <origin rpy="3.141592653589793 3.141592653589793 1.5707963267948966" xyz="0.0 0.0 0.0"/>
      <geometry>
        <mesh filename="package://sobit_mini_description/meshes/body/sobit_mini_small_gear.stl"/>
      </geometry>
      <material name="black"/>
    </visual>
    <collision>
      <origin rpy="3.141592653589793 3.141592653589793 1.5707963267948966" xyz="0.0 0.0 0.0"/>
      <geometry>
        <mesh filename="package://sobit_mini_description/meshes/body/sobit_mini_small_gear.stl"/>
      </geometry>
    </collision>
    <inertial>
      <origin rpy="0.0 0.0 0.0" xyz="0.0 0.0 0.0"/>
      <mass value="1"/>
      <inertia ixx="1.0" ixy="0.0" ixz="0.0" iyy="1.0" iyz="0.0" izz="1.0"/>
    </inertial>
  </link>
  <joint name="body_big_gear_base" type="fixed">
    <parent link="plate_middle_link"/>
    <child link="body_big_gear_base_link"/>
    <origin rpy="0.0 0.0 0.0" xyz="0.0 0.0 0.0031"/>
    <axis xyz="0 0 1"/>
  </joint>
  <link name="body_big_gear_base_link">
    <visual>
      <origin rpy="0.0 0.0 0.0" xyz="0.0 0.0 0.0"/>
      <geometry>
        <mesh filename="package://sobit_mini_description/meshes/body/big_gear_base.stl"/>
      </geometry>
      <material name="silver"/>
    </visual>
    <collision>
      <origin rpy="0.0 0.0 0.0" xyz="0.0 0.0 0.0"/>
      <geometry>
        <mesh filename="package://sobit_mini_description/meshes/body/sobit_mini_small_gear.stl"/>
      </geometry>
    </collision>
    <inertial>
      <origin rpy="0.0 0.0 0.0" xyz="0.0 0.0 0.0"/>
      <mass value="1"/>
      <inertia ixx="1.0" ixy="0.0" ixz="0.0" iyy="1.0" iyz="0.0" izz="1.0"/>
    </inertial>
  </link>
  <joint name="body_roll_joint" type="revolute">
    <parent link="body_big_gear_base_link"/>
    <child link="body_roll_link"/>
    <!-- <origin xyz="0.0 0.0 0.0" rpy="0.0 0.0 0.0" /> -->
    <origin rpy="0.0 0.0 0.0" xyz="0.0 0.0 0.0325"/>
    <axis xyz="0 0 1"/>
    <limit effort="30" lower="-1.5707963267948966" upper="1.5707963267948966" velocity="1.5707963267948966"/>
  </joint>
  <link name="body_roll_link">
    <visual>
      <origin rpy="0.0 0.0 0.0" xyz="0.0 0.0 0.0"/>
      <geometry>
        <mesh filename="package://sobit_mini_description/meshes/body/sobit_mini_big_gear.stl"/>
      </geometry>
      <material name="black"/>
    </visual>
    <collision>
      <origin rpy="0.0 0.0 0.0" xyz="0.0 0.0 0.0"/>
      <geometry>
        <mesh filename="package://sobit_mini_description/meshes/body/sobit_mini_big_gear.stl"/>
      </geometry>
    </collision>
    <inertial>
      <origin rpy="0.0 0.0 0.0" xyz="0.0 0.0 0.0"/>
      <mass value="1"/>
      <inertia ixx="1.0" ixy="0.0" ixz="0.0" iyy="1.0" iyz="0.0" izz="1.0"/>
    </inertial>
  </link>
  <joint name="body_big_gear_joint" type="fixed">
    <parent link="body_roll_link"/>
    <child link="body_big_gear_link"/>
    <origin rpy="0.0 0.0 0.0" xyz="0.0 0.0 0.0"/>
    <axis xyz="0 0 1"/>
  </joint>
  <link name="body_big_gear_link"/>
  <joint name="body_back_pole_joint" type="fixed">
    <!-- <parent link="${prefix}_big_gear_link" /> -->
    <parent link="body_roll_link"/>
    <child link="body_back_pole_link"/>
    <origin rpy="0.0 0.0 0.0" xyz="-0.01 0.0 0.058"/>
    <axis xyz="0 0 1"/>
  </joint>
  <link name="body_back_pole_link">
    <visual>
      <origin rpy="0 0 1.5707963267948966" xyz="0.0 0.0 0.0"/>
      <geometry>
        <mesh filename="package://sobit_mini_description/meshes/body/sobit_mini_center_back.stl"/>
      </geometry>
      <material name="black"/>
    </visual>
    <collision>
      <origin rpy="0 0 1.5707963267948966" xyz="0.0 0.0 0.0"/>
      <geometry>
        <mesh filename="package://sobit_mini_description/meshes/body/sobit_mini_center_back.stl"/>
      </geometry>
    </collision>
    <inertial>
      <origin rpy="0 0 0" xyz="0 0 0.0"/>
      <mass value="1"/>
      <inertia ixx="1.0" ixy="0.0" ixz="0.0" iyy="1.0" iyz="0.0" izz="1.0"/>
    </inertial>
  </link>
  <joint name="body_front_pole_joint" type="fixed">
    <!-- <parent link="${prefix}_big_gear_link" /> -->
    <parent link="body_roll_link"/>
    <child link="body_front_pole_link"/>
    <origin rpy="0.0 0.0 0.0" xyz="0.0 0.0 0.0005"/>
    <axis xyz="0 0 1"/>
  </joint>
  <link name="body_front_pole_link">
    <visual>
      <origin rpy="0.0 0.0 1.5707963267948966" xyz="0.0 0.0 0.0"/>
      <geometry>
        <mesh filename="package://sobit_mini_description/meshes/body/spine.stl"/>
      </geometry>
      <material name="black"/>
    </visual>
    <collision>
      <origin rpy="0.0 0.0 1.5707963267948966" xyz="0.0 0.0 0.0"/>
      <geometry>
        <mesh filename="package://sobit_mini_description/meshes/body/spine.stl"/>
      </geometry>
    </collision>
    <inertial>
      <origin rpy="0.0 0.0 0.0" xyz="0.0 0.0 0.0"/>
      <mass value="1"/>
      <inertia ixx="1.0" ixy="0.0" ixz="0.0" iyy="1.0" iyz="0.0" izz="1.0"/>
    </inertial>
  </link>
  <joint name="body_sobit_mini_cover" type="fixed">
    <!-- <parent link="${prefix}_big_gear_link" /> -->
    <parent link="body_roll_link"/>
    <child link="body_sobit_mini_cover"/>
    <origin rpy="0.0 0.0 0.0" xyz="0.0 0.0 0.0"/>
    <axis xyz="0 0 1"/>
  </joint>
  <link name="body_sobit_mini_cover">
    <visual>
      <origin rpy="0.0 0.0 1.5707963267948966" xyz="0.0 0.0 0.459"/>
      <geometry>
        <mesh filename="package://sobit_mini_description/meshes/body/sobit_mini_body_cover.dae"/>
      </geometry>
    </visual>
    <collision>
      <origin rpy="0.0 0.0 1.5707963267948966" xyz="0.0 0.0 0.459"/>
      <geometry>
        <mesh filename="package://sobit_mini_description/meshes/body/sobit_mini_body_cover.dae"/>
      </geometry>
    </collision>
    <inertial>
      <origin rpy="0 0 0" xyz="0 0 0.0"/>
      <mass value="1"/>
      <inertia ixx="1.0" ixy="0.0" ixz="0.0" iyy="1.0" iyz="0.0" izz="1.0"/>
    </inertial>
  </link>
  <!--position_joint_transmission joint="${prefix}_lift_joint" reduction="1" /-->
  <position_joint_transmission joint="body_roll_joint" reduction="1"/>
  <joint name="l_arm_shoulder_fixed_joint" type="fixed">
    <parent link="body_front_pole_link"/>
    <child link="l_arm_shoulder_fixed_link"/>
    <origin rpy="0 0 0" xyz="0.0 0.0 0.375988"/>
    <axis xyz="0 0 1"/>
    <limit effort="30" lower="-0.1" upper="0.1" velocity="1.571"/>
  </joint>
  <link name="l_arm_shoulder_fixed_link">
    <visual>
      <origin rpy="0.0 0.0 1.5707963267948966" xyz="0.0 0.0 0.0"/>
      <geometry>
        <mesh filename="package://sobit_mini_description/meshes/L_arm/L_ARM_SHOULDER_ROLL_JOINT.stl"/>
      </geometry>
      <material name="black"/>
    </visual>
    <collision>
      <origin rpy="0.0 0.0 1.5707963267948966" xyz="0.0 0.0 0.0"/>
      <geometry>
        <mesh filename="package://sobit_mini_description/meshes/L_arm/L_ARM_SHOULDER_ROLL_JOINT.stl"/>
      </geometry>
    </collision>
    <inertial>
      <origin rpy="0.0 0.0 0.0" xyz="0.0 0.0 0.0"/>
      <mass value="0.08"/>
      <inertia ixx="1.0" ixy="0.0" ixz="0.0" iyy="1.0" iyz="0.0" izz="1.0"/>
    </inertial>
  </link>
  <joint name="l_arm_shoulder_roll_joint" type="revolute">
    <parent link="l_arm_shoulder_fixed_link"/>
    <child link="l_arm_shoulder_roll_link"/>
    <origin rpy="0 0 0" xyz="0.0 0.1415 0.015161"/>
    <axis xyz="0 1 0"/>
    <limit effort="30" lower="-3.141592653589793" upper="1.5707963267948966" velocity="3.141592653589793"/>
  </joint>
  <link name="l_arm_shoulder_roll_link">
    <visual>
      <origin rpy="0.0 0.0 1.5707963267948966" xyz="0.0 0.0 0.0"/>
      <geometry>
        <mesh filename="package://sobit_mini_description/meshes/L_arm/L_ARM_SHOULDER_FLEX_JOINT.stl"/>
      </geometry>
      <material name="black"/>
    </visual>
    <collision>
      <origin rpy="0.0 0.0 1.5707963267948966" xyz="0.0 0.0 0.0"/>
      <geometry>
        <mesh filename="package://sobit_mini_description/meshes/L_arm/L_ARM_SHOULDER_FLEX_JOINT.stl"/>
      </geometry>
    </collision>
    <inertial>
      <origin rpy="0 0 0" xyz="0.0 0.0 0.0"/>
      <mass value="0.08"/>
      <inertia ixx="1.0" ixy="0.0" ixz="0.0" iyy="1.0" iyz="0.0" izz="1.0"/>
    </inertial>
  </link>
  <joint name="l_arm_shoulder_pan_joint" type="revolute">
    <parent link="l_arm_shoulder_roll_link"/>
    <child link="l_arm_shoulder_pan_link"/>
    <origin rpy="0 0 0" xyz="0.0 0.05375 0.0"/>
    <axis xyz="1 0 0"/>
    <limit effort="30" lower="-1.5707963267948966" upper="1.5707963267948966" velocity="1.5707963267948966"/>
  </joint>
  <link name="l_arm_shoulder_pan_link">
    <visual>
      <origin rpy="0.0 0.0 1.5707963267948966" xyz="0.0 0.0 0.0"/>
      <geometry>
        <mesh filename="package://sobit_mini_description/meshes/L_arm/L_ARM_ELBOW_TILT_JOINT.stl"/>
      </geometry>
      <material name="black"/>
    </visual>
    <collision>
      <origin rpy="0.0 0.0 1.5707963267948966" xyz="0.0 0.0 0.0"/>
      <geometry>
        <mesh filename="package://sobit_mini_description/meshes/L_arm/L_ARM_ELBOW_TILT_JOINT.stl"/>
      </geometry>
    </collision>
    <inertial>
      <origin rpy="0 0 0" xyz="0.0 0.0 0.0"/>
      <mass value="0.08"/>
      <inertia ixx="1.0" ixy="0.0" ixz="0.0" iyy="1.0" iyz="0.0" izz="1.0"/>
    </inertial>
  </link>
  <joint name="l_arm_elbow_tilt_joint" type="revolute">
    <parent link="l_arm_shoulder_pan_link"/>
    <child link="l_arm_elbow_tilt_link"/>
    <origin rpy="0 0 0" xyz="0 0.11125 0"/>
    <axis xyz="0 0 1"/>
    <limit effort="30" lower="-1.5707963267948966" upper="0.0" velocity="1.5707963267948966"/>
  </joint>
  <link name="l_arm_elbow_tilt_link">
    <visual>
      <origin rpy="0.0 0.0 1.5707963267948966" xyz="0.0 0.0 0.0"/>
      <geometry>
        <mesh filename="package://sobit_mini_description/meshes/L_arm/L_ARM_WRIST_TILT_JOINT.stl"/>
      </geometry>
      <material name="black"/>
    </visual>
    <collision>
      <origin rpy="0.0 0.0 1.5707963267948966" xyz="0.0 0.0 0.0"/>
      <geometry>
        <mesh filename="package://sobit_mini_description/meshes/L_arm/L_ARM_WRIST_TILT_JOINT.stl"/>
      </geometry>
    </collision>
    <inertial>
      <origin rpy="0 0 0" xyz="0.0 0.0 0.0"/>
      <mass value="0.08"/>
      <inertia ixx="1.0" ixy="0.0" ixz="0.0" iyy="1.0" iyz="0.0" izz="1.0"/>
    </inertial>
  </link>
  <joint name="l_arm_wrist_tilt_joint" type="revolute">
    <parent link="l_arm_elbow_tilt_link"/>
    <child link="l_arm_wrist_tilt_link"/>
    <origin rpy="0 0 0" xyz="0 0.10275 0"/>
    <axis xyz="0 0 1"/>
    <limit effort="30" lower="-1.5707963267948966" upper="1.5707963267948966" velocity="1.5707963267948966"/>
  </joint>
  <link name="l_arm_wrist_tilt_link">
    <visual>
      <origin rpy="0.0 -1.5707963267948966 3.141592653589793" xyz="0.0 0.0 0.0"/>
      <geometry>
        <mesh filename="package://sobit_mini_description/meshes/L_hand/L_hand_JOINT.stl"/>
      </geometry>
      <material name="black"/>
    </visual>
    <collision>
      <origin rpy="0.0 -1.5707963267948966 3.141592653589793" xyz="0.0 0.0 0.0"/>
      <geometry>
        <mesh filename="package://sobit_mini_description/meshes/L_hand/L_hand_JOINT.stl"/>
      </geometry>
    </collision>
    <inertial>
      <origin rpy="0.0 0.0 0.0" xyz="0.0 0.0 0.0"/>
      <mass value="0.08"/>
      <inertia ixx="1.0" ixy="0.0" ixz="0.0" iyy="1.0" iyz="0.0" izz="1.0"/>
    </inertial>
  </link>
  <position_joint_transmission joint="l_arm_shoulder_roll_joint" reduction="1"/>
  <position_joint_transmission joint="l_arm_shoulder_pan_joint" reduction="1"/>
  <position_joint_transmission joint="l_arm_elbow_tilt_joint" reduction="1"/>
  <position_joint_transmission joint="l_arm_wrist_tilt_joint" reduction="1"/>
  <joint name="r_arm_shoulder_fixed_joint" type="fixed">
    <parent link="body_front_pole_link"/>
    <child link="r_arm_shoulder_fixed_link"/>
    <origin rpy="0 0 0" xyz="0.0 0.0 0.375988"/>
    <axis xyz="0 0 1"/>
    <limit effort="30" lower="-0.1" upper="0.1" velocity="1.571"/>
  </joint>
  <link name="r_arm_shoulder_fixed_link">
    <collision>
      <origin rpy="0.0 0.0 1.5707963267948966" xyz="0 0 0"/>
      <geometry>
        <mesh filename="package://sobit_mini_description/meshes/R_arm/R_ARM_SHOULDER_ROLL_JOINT.stl"/>
      </geometry>
    </collision>
    <visual>
      <origin rpy="0.0 0.0 1.5707963267948966" xyz="0 0 0"/>
      <geometry>
        <mesh filename="package://sobit_mini_description/meshes/R_arm/R_ARM_SHOULDER_ROLL_JOINT.stl"/>
      </geometry>
      <material name="black"/>
    </visual>
    <inertial>
      <origin rpy="0 0 0" xyz="0.0 0.0 0.0"/>
      <mass value="0.08"/>
      <inertia ixx="1.0" ixy="0.0" ixz="0.0" iyy="1.0" iyz="0.0" izz="1.0"/>
    </inertial>
  </link>
  <joint name="r_arm_shoulder_roll_joint" type="revolute">
    <parent link="r_arm_shoulder_fixed_link"/>
    <child link="r_arm_shoulder_roll_link"/>
    <origin rpy="0 0 0" xyz="0.0 -0.1415 0.015161"/>
    <axis xyz="0 -1 0"/>
    <limit effort="30" lower="-1.5707963267948966" upper="3.141592653589793" velocity="1.5707963267948966"/>
  </joint>
  <link name="r_arm_shoulder_roll_link">
    <collision>
      <origin rpy="0.0 0 1.5707963267948966" xyz="0.0 0.0 0.0"/>
      <geometry>
        <mesh filename="package://sobit_mini_description/meshes/R_arm/R_ARM_SHOULDER_FLEX_JOINT.stl"/>
      </geometry>
    </collision>
    <visual>
      <origin rpy="0.0 0 1.5707963267948966" xyz="0.0 0.0 0.0"/>
      <geometry>
        <mesh filename="package://sobit_mini_description/meshes/R_arm/R_ARM_SHOULDER_FLEX_JOINT.stl"/>
      </geometry>
      <material name="black"/>
    </visual>
    <inertial>
      <origin rpy="0 0 0" xyz="0.0 0 0.0"/>
      <mass value="0.08"/>
      <inertia ixx="1.0" ixy="0.0" ixz="0.0" iyy="1.0" iyz="0.0" izz="1.0"/>
    </inertial>
  </link>
  <joint name="r_arm_shoulder_pan_joint" type="revolute">
    <parent link="r_arm_shoulder_roll_link"/>
    <child link="r_arm_shoulder_pan_link"/>
    <origin rpy="0 0 0" xyz="0.0 -0.05375 0.0"/>
    <axis xyz="1 0 0"/>
    <limit effort="30" lower="-1.5707963267948966" upper="1.5707963267948966" velocity="1.5707963267948966"/>
  </joint>
  <link name="r_arm_shoulder_pan_link">
    <collision>
      <origin rpy="1.5707963267948966 0.0 1.5707963267948966" xyz="0.0 0.0 0.0"/>
      <geometry>
        <mesh filename="package://sobit_mini_description/meshes/R_arm/R_ARM_ELBOW_TILT_JOINT.stl"/>
      </geometry>
    </collision>
    <visual>
      <origin rpy="1.5707963267948966 0.0 1.5707963267948966" xyz="0.0 0.0 0.0"/>
      <geometry>
        <mesh filename="package://sobit_mini_description/meshes/R_arm/R_ARM_ELBOW_TILT_JOINT.stl"/>
      </geometry>
      <material name="black"/>
    </visual>
    <inertial>
      <origin rpy="0 0 0" xyz="0.0 0.0 0.0"/>
      <mass value="0.08"/>
      <inertia ixx="1.0" ixy="0.0" ixz="0.0" iyy="1.0" iyz="0.0" izz="1.0"/>
    </inertial>
  </link>
  <joint name="r_arm_elbow_tilt_joint" type="revolute">
    <parent link="r_arm_shoulder_pan_link"/>
    <child link="r_arm_elbow_tilt_link"/>
    <origin rpy="0 0 0" xyz="0 -0.11125 0"/>
    <axis xyz="0 0 1"/>
    <limit effort="30" lower="0.0" upper="1.5707963267948966" velocity="1.5707963267948966"/>
  </joint>
  <link name="r_arm_elbow_tilt_link">
    <collision>
      <origin rpy="0.0 0.0 1.5707963267948966" xyz="0.0 0.0 0.0"/>
      <geometry>
        <mesh filename="package://sobit_mini_description/meshes/R_arm/R_ARM_WRIST_TILT_JOINT.stl"/>
      </geometry>
    </collision>
    <visual>
      <origin rpy="0.0 0.0 1.5707963267948966" xyz="0.0 0.0 0.0"/>
      <geometry>
        <mesh filename="package://sobit_mini_description/meshes/R_arm/R_ARM_WRIST_TILT_JOINT.stl"/>
      </geometry>
      <material name="black"/>
    </visual>
    <inertial>
      <origin rpy="0 0 0" xyz="0.0 0.0 0.0"/>
      <mass value="0.08"/>
      <inertia ixx="1.0" ixy="0.0" ixz="0.0" iyy="1.0" iyz="0.0" izz="1.0"/>
    </inertial>
  </link>
  <joint name="r_arm_wrist_tilt_joint" type="revolute">
    <parent link="r_arm_elbow_tilt_link"/>
    <child link="r_arm_wrist_tilt_link"/>
    <origin rpy="0 0 0" xyz="0 -0.10275 0"/>
    <axis xyz="0 0 1"/>
    <limit effort="30" lower="-1.5707963267948966" upper="1.5707963267948966" velocity="1.5707963267948966"/>
  </joint>
  <link name="r_arm_wrist_tilt_link">
    <visual>
      <origin rpy="0.0 1.5707963267948966 0.0" xyz="0.0 0.0 0.0"/>
      <geometry>
        <mesh filename="package://sobit_mini_description/meshes/R_hand/R_hand_JOINT.stl"/>
      </geometry>
      <material name="black"/>
    </visual>
    <collision>
      <origin rpy="0.0 1.5707963267948966 0.0" xyz="0.0 0.0 0.0"/>
      <geometry>
        <mesh filename="package://sobit_mini_description/meshes/R_hand/R_hand_JOINT.stl"/>
      </geometry>
    </collision>
    <inertial>
      <origin rpy="0.0 0.0 0.0" xyz="0.0 0.0 0.0"/>
      <mass value="0.08"/>
      <inertia ixx="1.0" ixy="0.0" ixz="0.0" iyy="1.0" iyz="0.0" izz="1.0"/>
    </inertial>
  </link>
  <position_joint_transmission joint="r_arm_shoulder_roll_joint" reduction="1"/>
  <position_joint_transmission joint="r_arm_shoulder_pan_joint" reduction="1"/>
  <position_joint_transmission joint="r_arm_elbow_tilt_joint" reduction="1"/>
  <position_joint_transmission joint="r_arm_wrist_tilt_joint" reduction="1"/>
  <!-- <joint name="${prefix}_base_joint" type="fixed">
      <parent link="${parent}" />
      <child link="${prefix}_base_link" />
      <origin rpy="${M_PI/2.0} ${-M_PI/2.0} 0" xyz="0.0 0.0 0.0" />
      <axis xyz="1 0 0" />
      <limit lower="${-M_PI/2.0}" upper="${M_PI/2.0}" effort="30" velocity="${M_PI/2.0}" />
    </joint>

    <link name="${prefix}_base_link"/> -->
  <!-- <joint name="${prefix}_right_finger_joint" type="revolute"> -->
  <joint name="l_hand_joint" type="revolute">
    <!-- <parent link="${prefix}_base_link" /> -->
    <parent link="l_arm_wrist_tilt_link"/>
    <child link="l_hand_right_finger_link"/>
    <!-- <origin rpy="0 0 0" xyz="-0.015855 0.0 -0.04725" /> -->
    <origin rpy="1.5707963267948966 -1.5707963267948966 0" xyz="0.0 0.04725 -0.015855"/>
    <!-- <origin rpy="${M_PI/2.0} ${-M_PI/2.0} 0" xyz="-0.015855 0.0 -0.04725" /> -->
    <axis xyz="0 -1 0"/>
    <limit effort="30" lower="-1.0" upper="0.0" velocity="1.5707963267948966"/>
  </joint>
  <link name="l_hand_right_finger_link">
    <visual>
      <origin rpy="1.5707963267948966 0.0 0.0" xyz="0.0 0.0 0.0"/>
      <geometry>
        <mesh filename="package://sobit_mini_description/meshes/L_hand/L_hand_finger_r_joint.stl"/>
      </geometry>
      <material name="black"/>
    </visual>
    <collision>
      <origin rpy="1.5707963267948966 0.0 0.0" xyz="0.0 0.0 0.0"/>
      <geometry>
        <mesh filename="package://sobit_mini_description/meshes/L_hand/L_hand_finger_r_joint.stl"/>
      </geometry>
    </collision>
    <inertial>
      <origin rpy="0.0 0.0 0.0" xyz="0.0 0.0 0.0"/>
      <mass value="0.08"/>
      <inertia ixx="1.0" ixy="0.0" ixz="0.0" iyy="1.0" iyz="0.0" izz="1.0"/>
    </inertial>
  </link>
  <joint name="l_hand_left_finger_joint" type="revolute">
    <!-- <parent link="${prefix}_base_link" /> -->
    <parent link="l_arm_wrist_tilt_link"/>
    <child link="l_hand_left_finger_link"/>
    <!-- <origin rpy="0 0 0" xyz="0.015855 0.0 -0.04725" /> -->
    <origin rpy="1.5707963267948966 -1.5707963267948966 0" xyz="0.0 0.04725 0.015855"/>
    <axis xyz="0 1 0"/>
    <limit effort="30" lower="0.0" upper="1.0" velocity="1.5707963267948966"/>
    <!-- <mimic joint="${prefix}_right_finger_joint" multiplier="1.0" /> -->
    <mimic joint="l_hand_joint" multiplier="1.0"/>
  </joint>
  <link name="l_hand_left_finger_link">
    <visual>
      <origin rpy="1.5707963267948966 0.0 0.0" xyz="0.0 0.0 0.0"/>
      <geometry>
        <mesh filename="package://sobit_mini_description/meshes/L_hand/L_hand_finger_l_joint.stl"/>
      </geometry>
      <material name="black"/>
    </visual>
    <collision>
      <origin rpy="1.5707963267948966 0.0 0.0" xyz="0.0 0.0 0.0"/>
      <geometry>
        <mesh filename="package://sobit_mini_description/meshes/L_hand/L_hand_finger_l_joint.stl"/>
      </geometry>
    </collision>
    <inertial>
      <origin rpy="0.0 0.0 0.0" xyz="0 0 0"/>
      <mass value="0.08"/>
      <inertia ixx="1.0" ixy="0.0" ixz="0.0" iyy="1.0" iyz="0.0" izz="1.0"/>
    </inertial>
  </link>
  <position_joint_transmission joint="l_hand_motor_joint" reduction="1"/>
  <!-- <joint name="${prefix}_base_joint" type="fixed">
      <parent link="${parent}" />
      <child link="${prefix}_base_link" />
      <origin  rpy="${-M_PI/2.0} ${M_PI/2.0} 0" xyz="0.0 0.0 0.0"/>
      <axis xyz="-1 0 0" />
      <limit lower="${-M_PI/2.0}" upper="${M_PI/2.0}" effort="30" velocity="${M_PI/2.0}" />
    </joint>

    <link name="${prefix}_base_link"/> -->
  <!-- <joint name="${prefix}_left_finger_joint" type="revolute"> -->
  <joint name="r_hand_joint" type="revolute">
    <!-- <parent link="${prefix}_base_link" /> -->
    <parent link="r_arm_wrist_tilt_link"/>
    <child link="r_hand_left_finger_link"/>
    <!-- <origin rpy="0 0 0" xyz="0.015855 0.0 -0.04725" /> -->
    <origin rpy="-1.5707963267948966 1.5707963267948966 0" xyz="0.0 -0.04725 -0.015855"/>
    <axis xyz="0 -1 0"/>
    <limit effort="30" lower="0" upper="1" velocity="1.5707963267948966"/>
  </joint>
  <link name="r_hand_left_finger_link">
    <visual>
      <origin rpy="1.5707963267948966 0.0 0.0" xyz="0.0 0.0 0.0"/>
      <geometry>
        <mesh filename="package://sobit_mini_description/meshes/R_hand/R_hand_finger_l_joint.stl"/>
      </geometry>
      <material name="black"/>
    </visual>
    <collision>
      <origin rpy="1.5707963267948966 0.0 0.0" xyz="0.0 0.0 0.0"/>
      <geometry>
        <mesh filename="package://sobit_mini_description/meshes/R_hand/R_hand_finger_l_joint.stl"/>
      </geometry>
    </collision>
    <inertial>
      <origin rpy="0.0 0.0 0.0" xyz="0.0 0.0 0.0"/>
      <mass value="0.08"/>
      <inertia ixx="1.0" ixy="0.0" ixz="0.0" iyy="1.0" iyz="0.0" izz="1.0"/>
    </inertial>
  </link>
  <joint name="r_hand_right_finger_joint" type="revolute">
    <!-- <parent link="${prefix}_base_link" /> -->
    <parent link="r_arm_wrist_tilt_link"/>
    <child link="r_hand_right_finger_link"/>
    <!-- <origin rpy="0 0 0" xyz="-0.015855 0.0 -0.04725" /> -->
    <origin rpy="-1.5707963267948966 1.5707963267948966 0" xyz="0.0 -0.04725 0.015855"/>
    <axis xyz="0 1 0"/>
    <limit effort="30" lower="-1.0" upper="0.0" velocity="1.5707963267948966"/>
    <!-- <mimic joint="${prefix}_left_finger_joint" multiplier="1.0" /> -->
    <mimic joint="r_hand_joint" multiplier="1.0"/>
  </joint>
  <link name="r_hand_right_finger_link">
    <visual>
      <origin rpy="1.5707963267948966 0.0 0.0" xyz="0.0 0.0 0.0"/>
      <geometry>
        <mesh filename="package://sobit_mini_description/meshes/R_hand/R_hand_finger_r_joint.stl"/>
      </geometry>
      <material name="black"/>
    </visual>
    <collision>
      <origin rpy="1.5707963267948966 0.0 0.0" xyz="0.0 0.0 0.0"/>
      <geometry>
        <mesh filename="package://sobit_mini_description/meshes/R_hand/R_hand_finger_r_joint.stl"/>
      </geometry>
    </collision>
    <inertial>
      <origin rpy="0.0 0.0 0.0" xyz="0.0 0.0 0.0"/>
      <mass value="0.08"/>
      <inertia ixx="1.0" ixy="0.0" ixz="0.0" iyy="1.0" iyz="0.0" izz="1.0"/>
    </inertial>
  </link>
  <position_joint_transmission joint="r_hand_motor_joint" reduction="1"/>
  <joint name="head_pan_joint" type="revolute">
    <parent link="body_front_pole_link"/>
    <child link="head_pan_link"/>
    <origin rpy="0.0 0.0 0.0" xyz="0.0 0.0 0.516"/>
    <axis xyz="0 0 1"/>
    <limit effort="30" lower="-2.617" upper="2.617" velocity="1.5707963267948966"/>
  </joint>
  <link name="head_pan_link">
    <visual>
      <origin rpy="0.0 0.0 1.5707963267948966" xyz="0.0 0.0 0.0"/>
      <geometry>
        <mesh filename="package://sobit_mini_description/meshes/head/HEAD_PAN_JOINT.stl"/>
      </geometry>
      <material name="black"/>
    </visual>
    <collision>
      <origin rpy="0.0 0.0 1.5707963267948966" xyz="0.0 0.0 0.0"/>
      <geometry>
        <mesh filename="package://sobit_mini_description/meshes/head/HEAD_PAN_JOINT.stl"/>
      </geometry>
    </collision>
    <inertial>
      <origin rpy="1.5707963267948966 0 0" xyz="0 0 0.0135"/>
      <mass value="0.6"/>
      <inertia ixx="1.0" ixy="0.0" ixz="0.0" iyy="1.0" iyz="0.0" izz="1.0"/>
    </inertial>
  </link>
  <joint name="head_tilt_joint" type="revolute">
    <parent link="head_pan_link"/>
    <child link="head_tilt_link"/>
    <origin rpy="0.0 0.0 0.0" xyz="0.0 0.0 0.017"/>
    <axis xyz="0 -1 0"/>
    <limit effort="30" lower="-1" upper="1" velocity="1.5707963267948966"/>
  </joint>
  <link name="head_tilt_link">
    <visual>
      <origin rpy="0.0 0.0 1.5707963267948966" xyz="0.0 0.0 0.0"/>
      <geometry>
        <mesh filename="package://sobit_mini_description/meshes/head/HEAD_TILT_JOINT.dae"/>
      </geometry>
    </visual>
    <collision>
      <origin rpy="0.0 0.0 1.5707963267948966" xyz="0.0 0.0 0.0"/>
      <geometry>
        <mesh filename="package://sobit_mini_description/meshes/head/HEAD_TILT_JOINT.dae"/>
      </geometry>
    </collision>
    <inertial>
      <origin rpy="1.5707963267948966 0 0" xyz="0 0 -0.031"/>
      <mass value="0.3"/>
      <inertia ixx="1.0" ixy="0.0" ixz="0.0" iyy="1.0" iyz="0.0" izz="1.0"/>
    </inertial>
  </link>
  <position_joint_transmission joint="head_pan_joint" reduction="1"/>
  <position_joint_transmission joint="head_tilt_joint" reduction="1"/>
  <joint name="head_camera_base_joint" type="fixed">
    <!-- <origin xyz="0.0908687 0.0 -0.01539994" rpy="0.0 0.0 0.0" /> -->
    <origin rpy="0.0 0.0 0.0" xyz="0.0045 0.0 0.169655"/>
    <parent link="head_tilt_link"/>
    <child link="head_camera_base_link"/>
  </joint>
  <link name="head_camera_base_link"/>
  <!-- camera body, with origin at bottom screw mount -->
  <joint name="head_camera_joint" type="fixed">
    <origin rpy="0.0 0.0 0.0" xyz="0.0 0.0 0.0"/>
    <parent link="head_camera_base_link"/>
    <child link="head_camera_bottom_screw_frame"/>
  </joint>
  <link name="head_camera_bottom_screw_frame"/>
  <joint name="head_camera_link_joint" type="fixed">
    <origin rpy="0 0 0" xyz="0.010600000000000002 0.0175 0.0125"/>
    <parent link="head_camera_bottom_screw_frame"/>
    <child link="head_camera_link"/>
  </joint>
  <link name="head_camera_link">
    <visual>
      <!-- the mesh origin is at front plate in between the two infrared camera axes -->
      <origin rpy="1.5707963267948966 0 1.5707963267948966" xyz="0.0043 -0.0175 0"/>
      <geometry>
        <mesh filename="package://realsense2_description/meshes/d435.dae"/>
      </geometry>
    </visual>
    <collision>
      <origin rpy="0 0 0" xyz="0 -0.0175 0"/>
      <geometry>
        <box size="0.02505 0.09 0.025"/>
      </geometry>
    </collision>
    <inertial>
      <!-- The following are not reliable values, and should not be used for modeling -->
      <mass value="0.072"/>
      <origin xyz="0 0 0"/>
      <inertia ixx="0.003881243" ixy="0.0" ixz="0.0" iyy="0.000498940" iyz="0.0" izz="0.003879257"/>
    </inertial>
  </link>
  <!-- camera depth joints and links -->
  <joint name="head_camera_depth_joint" type="fixed">
    <origin rpy="0 0 0" xyz="0 0 0"/>
    <parent link="head_camera_link"/>
    <child link="head_camera_depth_frame"/>
  </joint>
  <link name="head_camera_depth_frame"/>
  <joint name="head_camera_depth_optical_joint" type="fixed">
    <origin rpy="-1.5707963267948966 0 -1.5707963267948966" xyz="0 0 0"/>
    <parent link="head_camera_depth_frame"/>
    <child link="head_camera_depth_optical_frame"/>
  </joint>
  <link name="head_camera_depth_optical_frame"/>
  <!-- camera left IR joints and links -->
  <joint name="head_camera_infra1_joint" type="fixed">
    <origin rpy="0 0 0" xyz="0 0.0 0"/>
    <parent link="head_camera_link"/>
    <child link="head_camera_infra1_frame"/>
  </joint>
  <link name="head_camera_infra1_frame"/>
  <joint name="head_camera_infra1_optical_joint" type="fixed">
    <origin rpy="-1.5707963267948966 0 -1.5707963267948966" xyz="0 0 0"/>
    <parent link="head_camera_infra1_frame"/>
    <child link="head_camera_infra1_optical_frame"/>
  </joint>
  <link name="head_camera_infra1_optical_frame"/>
  <!-- camera right IR joints and links -->
  <joint name="head_camera_infra2_joint" type="fixed">
    <origin rpy="0 0 0" xyz="0 -0.05 0"/>
    <parent link="head_camera_link"/>
    <child link="head_camera_infra2_frame"/>
  </joint>
  <link name="head_camera_infra2_frame"/>
  <joint name="head_camera_infra2_optical_joint" type="fixed">
    <origin rpy="-1.5707963267948966 0 -1.5707963267948966" xyz="0 0 0"/>
    <parent link="head_camera_infra2_frame"/>
    <child link="head_camera_infra2_optical_frame"/>
  </joint>
  <link name="head_camera_infra2_optical_frame"/>
  <!-- camera color joints and links -->
  <joint name="head_camera_color_joint" type="fixed">
    <origin rpy="0 0 0" xyz="0 0.015 0"/>
    <parent link="head_camera_link"/>
    <child link="head_camera_color_frame"/>
  </joint>
  <link name="head_camera_color_frame"/>
  <joint name="head_camera_color_optical_joint" type="fixed">
    <origin rpy="-1.5707963267948966 0 -1.5707963267948966" xyz="0 0 0"/>
    <parent link="head_camera_color_frame"/>
    <child link="head_camera_color_optical_frame"/>
  </joint>
  <link name="head_camera_color_optical_frame"/>
  <joint name="mic_base_joint" type="fixed">
    <parent link="head_tilt_link"/>
    <child link="mic_base_link"/>
    <!-- <origin xyz="0.190 0.0 0.610" rpy="0.0 0.0 0.0" /> -->
    <origin rpy="0.0 0.0 0.0" xyz="-0.039589 0.0 0.169655"/>
  </joint>
  <link name="mic_base_link">
    <visual>
      <origin rpy="0.0 0.0 1.5707963267948966" xyz="0.0 0.0 0.0"/>
      <geometry>
        <mesh filename="package://sobit_mini_description/meshes/sensor/mic.stl"/>
      </geometry>
      <material name="black"/>
    </visual>
    <collision>
      <origin rpy="0.0 0.0 0.0" xyz="0.0 0.0 0.0"/>
      <geometry>
        <mesh filename="package://sobit_mini_description/meshes/sensor/mic.stl"/>
      </geometry>
      <material name="black"/>
    </collision>
    <inertial>
      <origin rpy="0.0 0.0 0.0" xyz="0.0 0.0 0.0"/>
      <mass value="1"/>
      <inertia ixx="1.0" ixy="0.0" ixz="0.0" iyy="1.0" iyz="0.0" izz="1.0"/>
    </inertial>
  </link>
  <!-- <link name="${prefix}_base_link">
      <visual>
        <origin xyz="0.0 0.0 0.0" rpy="${M_PI/2} 0 ${M_PI/2}" />
        <geometry>
          <mesh filename="package://sobit_edu_description/meshes/sensor/mic_base.stl" scale="0.001 0.001 0.001" />
        </geometry>
        <material name="black" />
      </visual>
      <collision>
        <origin xyz="0.0 0.0 0.0" rpy="${M_PI/2} 0 ${M_PI/2}" />
        <geometry>
          <mesh filename="package://sobit_edu_description/meshes/sensor/mic_base.stl" scale="0.001 0.001 0.001" />
        </geometry>
        <material name="black" />
      </collision>
      <inertial>
        <origin xyz="0.0 0.0 0.0" rpy="0 0 0" />
        <mass value="1" />
        <inertia ixx="1.0" ixy="0.0" ixz="0.0"
                 iyy="1.0" iyz="0.0"
                 izz="1.0" />
      </inertial>
    </link> -->
  <!-- <joint name="${prefix}_joint" type="fixed">
      <parent link="${prefix}_base_link" />
      <child link="${prefix}_link" />
      <origin xyz="-0.017007 0.0 0.020" rpy="0.0 0.0 0.0" />
    </joint> -->
  <!-- <link name="${prefix}_link"> -->
</robot>

