<?xml version="1.0"?>
<!--
  The common turtlebot library of xacros for easy reference
 -->
<robot xmlns:xacro="http://ros.org/wiki/xacro">
  <!-- General -->
  <xacro:include filename="$(find turtlebot_description)/urdf/common_properties.urdf.xacro"/>
  <xacro:include filename="$(find turtlebot_description)/urdf/turtlebot_properties.urdf.xacro"/>

  <!-- urg -->
  <joint name="laser" type="fixed">
    <origin xyz="0.205 0.0 0.01" rpy="0 0 0" />
    <parent link="base_link" />
    <child link="base_laser_link" />
  </joint>

  <link name="base_laser_link">
    <visual>
      <geometry>
        <mesh filename="package://sobit_mini_description/model/dae/UST-20LX.dae"/>
      </geometry>
      <material name="Black" />
    </visual>
    <inertial>
      <mass value="0.000001" />
      <origin xyz="0 0 0" />
      <inertia ixx="0.0001" ixy="0.0" ixz="0.0"
        iyy="0.0001" iyz="0.0"
        izz="0.0001" />
    </inertial>
  </link>

  <!-- add -->
<!-- ===============  Transmission =============== -->
  <transmission name="left_wheel_trans">
    <type>transmission_interface/SimpleTransmission</type>
    <joint name="left_wheel_joint">
      <hardwareInterface>VelocityJointInterface</hardwareInterface>
    </joint>
    <actuator name="left_wheel_motor">
      <hardwareInterface>VelocityJointInterface</hardwareInterface>
      <mechanicalReduction>30</mechanicalReduction>
    </actuator>
  </transmission>
  <transmission name="right_wheel_trans">
    <type>transmission_interface/SimpleTransmission</type>
    <joint name="right_wheel_joint">
      <hardwareInterface>VelocityJointInterface</hardwareInterface>
    </joint>
    <actuator name="right_wheel_motor">
      <hardwareInterface>VelocityJointInterface</hardwareInterface>
      <mechanicalReduction>30</mechanicalReduction>
    </actuator>
  </transmission>

  <!-- =============== Gazebo =============== -->
  <gazebo>
    <plugin name="gazebo_ros_control" filename="libgazebo_ros_control.so">
      <robotNamespace>my_robo</robotNamespace>
    </plugin>
  </gazebo>

  <gazebo reference="base_link">
    <selfCollide>true</selfCollide>
    <mu1 value="0.05" />
    <mu2 value="0.05" />
  </gazebo>

  <gazebo reference="left_wheel_link">
    <selfCollide>true</selfCollide>
    <mu1 value="0.8" />
    <mu2 value="0.8" />
  </gazebo>

  <gazebo reference="right_wheel_link">
    <selfCollide>true</selfCollide>
    <mu1 value="0.8" />
    <mu2 value="0.8" />
  </gazebo>

  <gazebo reference="caster_link">
    <selfCollide>true</selfCollide>
    <!-- This caster is no frictional resistance. -->
    <mu1 value="0.0" />
    <mu2 value="0.0" />
  </gazebo>


  <!-- urg gazebo -->
  <gazebo reference="base_laser_link">
    <sensor type="gpu_ray" name="head_hokuyo_sensor">
      <pose>0 0 0 0 0 0</pose>
      <visualize>false</visualize>
      <update_rate>40</update_rate>
      <ray>
        <scan>
          <horizontal>
            <samples>720</samples>
            <resolution>1</resolution>
            <min_angle>-1.570796</min_angle>
            <max_angle>1.570796</max_angle>
          </horizontal>
        </scan>
        <range>
          <min>0.10</min>
          <max>30.0</max>
          <resolution>0.01</resolution>
        </range>
        <noise>
          <type>gaussian</type>
          <!-- Noise parameters based on published spec for Hokuyo laser
               achieving "+-30mm" accuracy at range < 10m.  A mean of 0.0m and
               stddev of 0.01m will put 99.7% of samples within 0.03m of the true
               reading. -->
          <mean>0.0</mean>
          <stddev>0.01</stddev>
        </noise>
      </ray>
      <plugin name="gazebo_ros_head_hokuyo_controller" filename="libgazebo_ros_gpu_laser.so">
        <topicName>/rrbot/laser/scan</topicName>
        <frameName>base_laser_link</frameName>
      </plugin>
    </sensor>
  </gazebo>

  <!-- openplatform_sobit_mini_description -->
  <material name="red">
    <color rgba="1.0 0.0 0.0 1.0"/>
  </material>
  <material name="green">
    <color rgba="0.0 1.0 0.0 1.0"/>
  </material>
  <material name="blue">
    <color rgba="0.0 0.0 1.0 1.0"/>
  </material>
  <material name="black">
    <color rgba="0.0 0.0 0.0 1.0"/>
  </material>
  <material name="white">
    <color rgba="0.87 0.90 0.87 1.0"/>
  </material>
  <material name="orange">
    <color rgba="1.0 0.4 0.0 1.0"/>
  </material>

  <joint name="dmmy_joint_base" type="fixed">
    <parent link="plate_top_link"/>
    <child link="link1"/>
  </joint>

  <!-- Link 1 -->
  <link name="link1">
    <collision>
      <origin rpy="0 0 0" xyz="0.0 0 0.0175"/>
      <geometry>
        <box size="0.16 0.16 0.035"/>
      </geometry>
    </collision>
    <visual>
       <origin rpy="0 0 0" xyz="0.0 0 0.0175"/>
      <geometry>
        <box size="0.16 0.16 0.035"/>
      </geometry>
      <material name="black"/>
    </visual>
    <inertial>
      <origin rpy="0 0 0" xyz="0.0 0 0.0175"/>
      <mass value="0.08"/>
      <inertia ixx="1.0" ixy="0.0" ixz="0.0" iyy="1.0" iyz="0.0" izz="1.0"/>
    </inertial>
  </link>
  <joint name="joint1" type="continuous">
    <parent link="link1"/>
    <child link="link2"/>
   <origin rpy="0 0 0" xyz="0.0 0.0 0.035"/>
    <axis xyz="0 0 1"/>
    <limit effort="30" lower="-1.57" upper="1.57" velocity="1.571"/>
  </joint>

  <!-- Link 2 -->
  <link name="link2">
    <collision>
      <origin rpy="0 0 0" xyz="0.0 0 0.2"/>
      <geometry>
        <box size="0.02 0.02 0.4"/>
      </geometry>
    </collision>
    <visual>
      <origin rpy="0 0 0" xyz="0.0 0 0.2"/>
      <geometry>
        <box size="0.02 0.02 0.4"/>
      </geometry>
      <material name="black"/>
    </visual>
    <inertial>
      <origin rpy="0 0 0" xyz="0 0 0.2"/>
      <mass value="0.08"/>
      <inertia ixx="1.0" ixy="0.0" ixz="0.0" iyy="1.0" iyz="0.0" izz="1.0"/>
    </inertial>
  </link>

  <!-- Link 2.5 -->
  <link name="link2.5"/>

  <joint name="joint2" type="prismatic">
    <parent link="link2"/>
    <child link="link2.5"/>
    <origin rpy="0 0 1.57" xyz="0.0 0.0 0.4"/>
    <axis xyz="0 0 1"/>
    <limit effort="30" lower="0" upper="0.17" velocity="1.571"/>
  </joint>

  <joint name="dmmy_joint2.5_right" type="revolute">
    <parent link="link2.5"/>
    <child link="link3_right_arm"/>
    <origin rpy="0 0 0" xyz="0 0 0.0"/>
    <axis xyz="0 0 1"/>
    <limit effort="30" lower="-0.1" upper="0.1" velocity="1.571"/>
  </joint>

  <joint name="dmmy_joint2.5_left" type="revolute">
    <parent link="link2.5"/>
    <child link="link8_left_arm"/>
    <origin rpy="0 0 0" xyz="0 0 0.0"/>
    <axis xyz="0 0 1"/>
    <limit effort="30" lower="-0.1" upper="0.1" velocity="1.571"/>
  </joint>

  <joint name="dmmy_joint2.5_spine" type="revolute">
    <parent link="link2.5"/>
    <child link="link16_spine"/>
    <origin rpy="0 0 0" xyz="0 0 0.0"/>
    <axis xyz="0 0 1"/>
    <limit effort="30" lower="-0.1" upper="0.1" velocity="1.571"/>
  </joint>

  <joint name="dmmy_joint2.5_head" type="revolute">
    <parent link="link2.5"/>
    <child link="link13_head"/>
    <origin rpy="0 0 0" xyz="0 0 0.0"/>
    <axis xyz="0 0 1"/>
    <limit effort="30" lower="-0.1" upper="0.1" velocity="1.571"/>
  </joint>

<!-- right_arm -->
  <!-- Link 3 -->
  <link name="link3_right_arm">
    <collision>
      <origin rpy="0 0 0" xyz="0.06 0 0.0225"/>
      <geometry>
        <box size="0.12 0.03 0.045"/>
      </geometry>
    </collision>
    <visual>
      <origin rpy="0 0 0" xyz="0.06 0 0.0225"/>
      <geometry>
        <box size="0.12 0.03 0.045"/>
      </geometry>
      <material name="black"/>
    </visual>
    <inertial>
      <origin rpy="0 0 0" xyz="0.06 0 0.0225"/>
      <mass value="0.08"/>
      <inertia ixx="1.0" ixy="0.0" ixz="0.0" iyy="1.0" iyz="0.0" izz="1.0"/>
    </inertial>
  </link>
  <joint name="joint3" type="revolute">
    <parent link="link3_right_arm"/>
    <child link="link4"/>
    <origin rpy="0 0 0" xyz="0.12 0 0.0225"/>
    <axis xyz="1 0 0"/>
    <limit effort="30" lower="-2.35" upper="0" velocity="1.571"/>
  </joint>

  <!-- Link 4 -->
  <link name="link4">
    <collision>
      <origin rpy="0 0 0" xyz="0.0215 0 0.015"/>
      <geometry>
        <box size="0.043 0.04 0.03"/>
      </geometry>
    </collision>
    <visual>
      <origin rpy="0 0 0" xyz="0.0215 0 0.015"/>
      <geometry>
        <box size="0.043 0.04 0.03"/>
      </geometry>
      <material name="black"/>
    </visual>
    <inertial>
      <origin rpy="0 0 0" xyz="0.0215 0 0.015"/>
      <mass value="0.08"/>
      <inertia ixx="1.0" ixy="0.0" ixz="0.0" iyy="1.0" iyz="0.0" izz="1.0"/>
    </inertial>
  </link>
  <joint name="joint4" type="revolute">
    <parent link="link4"/>
    <child link="link5"/>
    <origin rpy="0 0 0" xyz="0.043 0.0 0.03"/>
    <axis xyz="0 1 0"/>
    <limit effort="30" lower="-2.35" upper="0" velocity="1.571"/>
  </joint>


  <!-- Link 5 -->
  <link name="link5">
    <collision>
      <origin rpy="0 0 0" xyz="0.0 0 -0.09"/>
      <geometry>
        <box size="0.035 0.05 0.18"/>
      </geometry>
    </collision>
    <visual>
      <origin rpy="0 0 0" xyz="0.0 0 -0.09"/>
      <geometry>
        <box size="0.035 0.05 0.18"/>
      </geometry>
      <material name="black"/>
    </visual>
    <inertial>
      <origin rpy="0 0 0" xyz="0 0 -0.04"/>
      <mass value="0.08"/>
      <inertia ixx="1.0" ixy="0.0" ixz="0.0" iyy="1.0" iyz="0.0" izz="1.0"/>
    </inertial>
  </link>
  <joint name="joint5" type="revolute">
    <parent link="link5"/>
    <child link="link5.5"/>
    <origin rpy="0 0 0" xyz="0 0 -0.18"/>
    <axis xyz="0 1 0"/>
    <limit effort="30" lower="-1.57" upper="1.57" velocity="1.571"/>
  </joint>

  <!-- Link 5.5 -->
  <link name="link5.5">
    <collision>
      <origin rpy="0 0 0" xyz="0.0 0 -0.025"/>
      <geometry>
        <box size="0.06 0.025 0.05"/>
      </geometry>
    </collision>
    <visual>
      <origin rpy="0 0 0" xyz="0.0 0 -0.025"/>
      <geometry>
        <box size="0.06 0.025 0.05"/>
      </geometry>
      <material name="black"/>
    </visual>
    <inertial>
      <origin rpy="0 0 0" xyz="0 0 -0.025"/>
      <mass value="0.08"/>
      <inertia ixx="1.0" ixy="0.0" ixz="0.0" iyy="1.0" iyz="0.0" izz="1.0"/>
    </inertial>
  </link>
  <joint name="dmmy_conect_joint_1" type="fixed">
    <parent link="link5.5"/>
    <child link="link6"/>
    <origin rpy="0 0 0" xyz="0 0 -0.05"/>
    <axis xyz="0 1 0"/>
    <limit effort="30" lower="-1.57" upper="1.57" velocity="1.571"/>
  </joint>

  <!-- Link 6 -->
  <link name="link6">
    <collision>
      <origin rpy="0 3.14 0" xyz="0.0 0 0"/>
      <geometry>
        <mesh filename="package://sobit_mini_description/model/dae/Manipulator_X4_Gripper_fix.dae"/>
      </geometry>
    </collision>
    <visual>
      <origin rpy="0 3.14 0" xyz="0.0 0 0"/>
      <geometry>
        <mesh filename="package://sobit_mini_description/model/dae/Manipulator_X4_Gripper_fix.dae"/>
      </geometry>
      <material name="black"/>
    </visual>
    <inertial>
      <origin rpy="0 3.14 0" xyz="0 0 0"/>
      <mass value="0.08"/>
      <inertia ixx="1.0" ixy="0.0" ixz="0.0" iyy="1.0" iyz="0.0" izz="1.0"/>
    </inertial>
  </link>

  <!-- right_arm_left_finger -->
	<joint name="right_arm_left_finger_joint" type="revolute">
		<parent link="link6"/>
		<child link="right_arm_left_finger"/>
        <origin rpy="0 0 0" xyz="0 0.018 -0.043"/>
        <axis xyz="1 0 0"/>
		<limit lower="-0.6" upper="0.8" effort="1" velocity="1" />
	</joint>

	<link name="right_arm_left_finger">
		<collision>
			<origin rpy="0 3.14 0" xyz="0 0 0"/>
			<geometry>
				<mesh filename="package://sobit_mini_description/model/dae/ManipulatorX4_Finger_right.dae"/>
			</geometry>
		</collision>
		<visual>
			<origin rpy="0 3.14 0" xyz="0 0 0"/>
			<geometry>
				<mesh filename="package://sobit_mini_description/model/dae/ManipulatorX4_Finger_right.dae"/>
			</geometry>
			<material name="black">
				<color rgba="0.0 0.0 0.0 1.0"/>
			</material>
		</visual>
		<inertial>
			<origin rpy="0 3.14 0" xyz="0 0 0"/>
			<mass value="0.08"/>
			<inertia ixx="1.0" ixy="0.0" ixz="0.0" iyy="1.0" iyz="0.0" izz="1.0"/>
		</inertial>
	</link>

  <!-- right_arm_right_finger -->
	<joint name="right_arm_right_fingerjoint" type="revolute">
		<parent link="link6"/>
		<child link="right_arm_right_finger"/>
        <origin rpy="0 0 0" xyz="0 -0.018 -0.043"/>
        <axis xyz="1 0 0"/>
		<limit lower="-0.8" upper="0.45" effort="1" velocity="1" />
	</joint>

	<link name="right_arm_right_finger">
		<collision>
			<origin rpy="0 3.14 0" xyz="0 0 0"/>
			<geometry>
				<mesh filename="package://sobit_mini_description/model/dae/ManipulatorX4_Finger_left.dae"/>
			</geometry>
		</collision>
		<visual>
			<origin rpy="0 3.14 0" xyz="0 0 0"/>
			<geometry>
				<mesh filename="package://sobit_mini_description/model/dae/ManipulatorX4_Finger_left.dae"/>
			</geometry>
			<material name="black">
				<color rgba="0.0 0.0 0.0 1.0"/>
			</material>
		</visual>
		<inertial>
			<origin rpy="0 3.14 0" xyz="0 0 0"/>
			<mass value="0.08"/>
			<inertia ixx="1.0" ixy="0.0" ixz="0.0" iyy="1.0" iyz="0.0" izz="1.0"/>
		</inertial>
	</link>

  <!-- right_arm_marker -->
  <link name="link7_right_arm_marker"/>
  <joint name="joint6_marker" type="revolute">
    <parent link="link6"/>
    <child link="link7_right_arm_marker"/>
    <origin rpy="0 0 0" xyz="0 0.0 -0.09"/>
    <axis xyz="1 0 0"/>
    <limit effort="30" lower="-0.1" upper="0.1" velocity="1.571"/>
  </joint>



<!-- left_arm -->
  <!-- Link 8 -->
  <link name="link8_left_arm">
    <collision>
      <origin rpy="0 0 0" xyz="-0.06 0 0.0225"/>
      <geometry>
        <box size="0.12 0.03 0.045"/>
      </geometry>
    </collision>
    <visual>
      <origin rpy="0 0 0" xyz="-0.06 0 0.0225"/>
      <geometry>
        <box size="0.12 0.03 0.045"/>
      </geometry>
      <material name="black"/>
    </visual>
    <inertial>
      <origin rpy="0 0 0" xyz="-0.06 0 0.0225"/>
      <mass value="0.08"/>
      <inertia ixx="1.0" ixy="0.0" ixz="0.0" iyy="1.0" iyz="0.0" izz="1.0"/>
    </inertial>
  </link>
  <joint name="joint7" type="revolute">
    <parent link="link8_left_arm"/>
    <child link="link9"/>
    <origin rpy="0 0 0" xyz="-0.12 0 0.0225"/>
    <axis xyz="1 0 0"/>
    <limit effort="30" lower="-2.35" upper="0" velocity="1.571"/>
  </joint>

  <!-- Link 9 -->
  <link name="link9">
    <collision>
      <origin rpy="0 0 0" xyz="-0.0215 0 0.015"/>
      <geometry>
        <box size="0.043 0.04 0.03"/>
      </geometry>
    </collision>
    <visual>
      <origin rpy="0 0 0" xyz="-0.0215 0 0.015"/>
      <geometry>
        <box size="0.043 0.04 0.03"/>
      </geometry>
      <material name="black"/>
    </visual>
    <inertial>
      <origin rpy="0 0 0" xyz="-0.0215 0 0.015"/>
      <mass value="0.08"/>
      <inertia ixx="1.0" ixy="0.0" ixz="0.0" iyy="1.0" iyz="0.0" izz="1.0"/>
    </inertial>
  </link>
  <joint name="joint8" type="revolute">
    <parent link="link9"/>
    <child link="link10"/>
    <origin rpy="0 0 0" xyz="-0.043 0.0 0.03"/>
    <axis xyz="0 1 0"/>
    <limit effort="30" lower="0" upper="2.35" velocity="1.571"/>
  </joint>


  <!-- Link 10 -->
  <link name="link10">
    <collision>
      <origin rpy="0 0 0" xyz="0.0 0 -0.09"/>
      <geometry>
        <box size="0.035 0.05 0.18"/>
      </geometry>
    </collision>
    <visual>
      <origin rpy="0 0 0" xyz="0.0 0 -0.09"/>
      <geometry>
        <box size="0.035 0.05 0.18"/>
      </geometry>
      <material name="black"/>
    </visual>
    <inertial>
      <origin rpy="0 0 0" xyz="0 0 -0.09"/>
      <mass value="0.08"/>
      <inertia ixx="1.0" ixy="0.0" ixz="0.0" iyy="1.0" iyz="0.0" izz="1.0"/>
    </inertial>
  </link>
  <joint name="joint9" type="revolute">
    <parent link="link10"/>
    <child link="link10.5"/>
    <origin rpy="0 0 0" xyz="0 0 -0.18"/>
    <axis xyz="0 1 0"/>
    <limit effort="30" lower="-1.57" upper="1.57" velocity="1.571"/>
  </joint>

  <!-- Link 10.5 -->
  <link name="link10.5">
    <collision>
      <origin rpy="0 0 0" xyz="0.0 0 -0.025"/>
      <geometry>
        <box size="0.06 0.025 0.05"/>
      </geometry>
    </collision>
    <visual>
      <origin rpy="0 0 0" xyz="0.0 0 -0.025"/>
      <geometry>
        <box size="0.06 0.025 0.05"/>
      </geometry>
      <material name="black"/>
    </visual>
    <inertial>
      <origin rpy="0 0 0" xyz="0 0 -0.025"/>
      <mass value="0.08"/>
      <inertia ixx="1.0" ixy="0.0" ixz="0.0" iyy="1.0" iyz="0.0" izz="1.0"/>
    </inertial>
  </link>
  <joint name="dmmy_conect_joint_2" type="fixed">
    <parent link="link10.5"/>
    <child link="link11"/>
    <origin rpy="0 0 0" xyz="0 0 -0.05"/>
    <axis xyz="0 1 0"/>
    <limit effort="30" lower="-1.57" upper="1.57" velocity="1.571"/>
  </joint>

  <!-- Link 11 -->
  <link name="link11">
    <collision>
      <origin rpy="0 3.14 0" xyz="0 0 0"/>
      <geometry>
        <mesh filename="package://sobit_mini_description/model/dae/Manipulator_X4_Gripper_fix.dae"/>
      </geometry>
    </collision>
    <visual>
	  <origin rpy="0 3.14 0" xyz="0 0 0"/>
      <geometry>
        <mesh filename="package://sobit_mini_description/model/dae/Manipulator_X4_Gripper_fix.dae"/>
      </geometry>
      <material name="black"/>
    </visual>
    <inertial>
      <origin rpy="0 3.14 0" xyz="0 0 0"/>
      <mass value="0.08"/>
      <inertia ixx="1.0" ixy="0.0" ixz="0.0" iyy="1.0" iyz="0.0" izz="1.0"/>
    </inertial>
  </link>

  <!-- left_arm_left_finger -->
	<joint name="left_arm_left_finger_joint" type="revolute">
		<parent link="link11"/>
		<child link="left_arm_left_finger"/>
        <origin rpy="0 0 0" xyz="0 0.018 -0.043"/>
        <axis xyz="1 0 0"/>
		<limit lower="-0.6" upper="0.8" effort="1" velocity="1" />
	</joint>

	<link name="left_arm_left_finger">
		<collision>
			<origin rpy="0 3.14 0" xyz="0 0 0"/>
			<geometry>
				<mesh filename="package://sobit_mini_description/model/dae/ManipulatorX4_Finger_right.dae"/>
			</geometry>
		</collision>
		<visual>
			<origin rpy="0 3.14 0" xyz="0 0 0"/>
			<geometry>
				<mesh filename="package://sobit_mini_description/model/dae/ManipulatorX4_Finger_right.dae"/>
			</geometry>
			<material name="black">
				<color rgba="0.0 0.0 0.0 1.0"/>
			</material>
		</visual>
		<inertial>
			<origin rpy="0 3.14 0" xyz="0 0 0"/>
			<mass value="0.08"/>
			<inertia ixx="1.0" ixy="0.0" ixz="0.0" iyy="1.0" iyz="0.0" izz="1.0"/>
		</inertial>
	</link>

  <!-- left_arm_right_finger -->
	<joint name="left_arm_right_finger_joint" type="revolute">
		<parent link="link11"/>
		<child link="left_arm_right_finger"/>
        <origin rpy="0 0 0" xyz="0 -0.018 -0.043"/>
        <axis xyz="1 0 0"/>
		<limit lower="-0.8" upper="0.45" effort="1" velocity="1" />
	</joint>

	<link name="left_arm_right_finger">
		<collision>
			<origin rpy="0 3.14 0" xyz="0 0 0"/>
			<geometry>
				<mesh filename="package://sobit_mini_description/model/dae/ManipulatorX4_Finger_left.dae"/>
			</geometry>
		</collision>
		<visual>
			<origin rpy="0 3.14 0" xyz="0 0 0"/>
			<geometry>
				<mesh filename="package://sobit_mini_description/model/dae/ManipulatorX4_Finger_left.dae"/>
			</geometry>
			<material name="black">
				<color rgba="0.0 0.0 0.0 1.0"/>
			</material>
		</visual>
		<inertial>
			<origin rpy="0 3.14 0" xyz="0 0 0"/>
			<mass value="0.08"/>
			<inertia ixx="1.0" ixy="0.0" ixz="0.0" iyy="1.0" iyz="0.0" izz="1.0"/>
		</inertial>
	</link>

<!-- head -->
  <!-- Link 13 -->
  <link name="link13_head">
    <collision>
      <origin rpy="0 0 0" xyz="0 0 0.0425"/>
      <geometry>
        <box size="0.043 0.04 0.085"/>
      </geometry>
    </collision>
    <visual>
      <origin rpy="0 0 0" xyz="0 0 0.0425"/>
      <geometry>
        <box size="0.043 0.04 0.085"/>
      </geometry>
      <material name="black"/>
    </visual>
    <inertial>
      <origin rpy="0 0 0" xyz="0 0 0.04255"/>
      <mass value="0.08"/>
      <inertia ixx="1.0" ixy="0.0" ixz="0.0" iyy="1.0" iyz="0.0" izz="1.0"/>
    </inertial>
  </link>
  <joint name="joint11" type="revolute">
    <parent link="link13_head"/>
    <child link="link14"/>
    <origin rpy="0 0 0" xyz="0 0 0.085"/>
    <axis xyz="0 0 1"/>
    <limit effort="30" lower="-3.14" upper="3.14" velocity="1.571"/>
  </joint>

  <!-- Link 14 -->
  <link name="link14">
    <collision>
      <origin rpy="0 0 0" xyz="0 0 0.021"/>
      <geometry>
        <box size="0.042 0.032 0.042"/>
      </geometry>
    </collision>
    <visual>
      <origin rpy="0 0 0" xyz="0 0 0.021"/>
      <geometry>
        <box size="0.042 0.032 0.042"/>
      </geometry>
      <material name="black"/>
    </visual>
    <inertial>
      <origin rpy="0 0 0" xyz="0 0 0.021"/>
      <mass value="0.08"/>
      <inertia ixx="1.0" ixy="0.0" ixz="0.0" iyy="1.0" iyz="0.0" izz="1.0"/>
    </inertial>
  </link>
  <joint name="joint12" type="revolute">
    <parent link="link14"/>
    <child link="link15"/>
    <origin rpy="0 0 0" xyz="0 0 0.042"/>
    <axis xyz="1 0 0"/>
    <limit effort="30" lower="-0.5" upper="1.57" velocity="1.571"/>
  </joint>

  <!-- Link 15 -->
  <link name="link15">
    <collision>
      <origin rpy="0 0 0" xyz="0 0 0.0775"/>
      <geometry>
        <box size="0.06 0.025 0.155"/>
      </geometry>
    </collision>
    <visual>
      <origin rpy="0 0 0" xyz="0 0 0.0775"/>
      <geometry>
        <box size="0.06 0.025 0.155"/>
      </geometry>
      <material name="black"/>
    </visual>
    <inertial>
      <origin rpy="0 0 0" xyz="0 0 0.0775"/>
      <mass value="0.08"/>
      <inertia ixx="1.0" ixy="0.0" ixz="0.0" iyy="1.0" iyz="0.0" izz="1.0"/>
    </inertial>
  </link>
  <joint name="dmmy_conect_joint_3" type="fixed">
    <parent link="link15"/>
    <child link="xtion"/>
    <origin rpy="0 0 -1.57" xyz="0 0 0.155"/>
    <axis xyz="0 1 0"/>
    <limit effort="30" lower="-1.57" upper="1.57" velocity="1.571"/>
  </joint>

  <!-- xtion -->
    <link name="xtion">
      <visual>
        <origin xyz="-0.0 0.0 0" rpy="0 0 0"/>
        <geometry>
          <mesh filename="package://turtlebot_description/meshes/sensors/xtion_pro_camera.dae"/>
        </geometry>
      </visual>
      <collision>
        <origin xyz="0.0 0.0 0.0" rpy="0 0 0" />
        <geometry>
        <box size="0.0730 0.2760 0.0720"/>
      </geometry>
      </collision>
      <inertial>
        <mass value="0.170" />
        <origin xyz="0 0 0" />
        <inertia ixx="0.001152600" ixy="0.0" ixz="0.0"
                 iyy="0.000148934" iyz="0.0"
                 izz="0.001154654" />
      </inertial>
    </link>

  <!-- rgb_link -->
  <link name="rgb_link"/>
  <joint name="rgb_link_xtion_joint" type="fixed">
    <parent link="xtion"/>
    <child link="rgb_link"/>
    <origin rpy="-1.57 0 -1.57" xyz="0 0.0205 0"/>
    <axis xyz="0 0 1"/>
    <limit effort="30" lower="-3.14" upper="3.14" velocity="1.571"/>
  </joint>


  <!-- depth_link -->
  <link name="depth_link"/>
  <joint name="depth_link_xtion_joint" type="fixed">
    <parent link="xtion"/>
    <child link="depth_link"/>
    <origin rpy="-1.57 0 -1.57" xyz="0 0.0475 0"/>
    <axis xyz="0 0 1"/>
    <limit effort="30" lower="-3.14" upper="3.14" velocity="1.571"/>
  </joint>

  <!-- Link 16 -->
  <link name="link16_spine">
    <collision>
      <origin rpy="0 0 0" xyz="0 0.035 -0.2"/>
      <geometry>
        <box size="0.02 0.03 0.4"/>
      </geometry>
    </collision>
    <visual>
      <origin rpy="0 0 0" xyz="0 0.035 -0.2"/>
      <geometry>
        <box size="0.02 0.03 0.4"/>
      </geometry>
      <material name="black"/>
    </visual>
    <inertial>
      <origin rpy="0 0 0" xyz="0 0.035 -0.2"/>
      <mass value="0.08"/>
      <inertia ixx="1.0" ixy="0.0" ixz="0.0" iyy="1.0" iyz="0.0" izz="1.0"/>
    </inertial>
  </link>

  <!-- left_arm_marker -->
  <link name="link12_left_arm_marker"/>
  <joint name="joint10_marker" type="revolute">
    <parent link="link11"/>
    <child link="link12_left_arm_marker"/>
    <origin rpy="0 0 0" xyz="0 0.0 -0.09"/>
    <axis xyz="1 0 0"/>
    <limit effort="30" lower="-0.1" upper="0.1" velocity="1.571"/>
  </joint>

</robot>
