<?xml version="1.0"?>
<!--
  The common turtlebot library of xacros for easy reference
 -->
<robot xmlns:xacro="http://ros.org/wiki/xacro">
  <!-- General -->
  <xacro:include filename="$(find turtlebot_description)/urdf/common_properties.urdf.xacro"/>
  <xacro:include filename="$(find turtlebot_description)/urdf/turtlebot_properties.urdf.xacro"/>

  <!-- urg -->
  <joint name="laser" type="fixed">
    <origin xyz="0.205 0.0 0.01" rpy="0 0 0" />
    <parent link="base_link" />
    <child link="base_laser_link" />
  </joint>

  <link name="base_laser_link">
    <visual>
      <geometry>
        <mesh filename="package://sobit_mini_description/model/dae/UST-20LX.dae"/>
      </geometry>
      <material name="Black" />
    </visual>
    <inertial>
      <mass value="0.000001" />
      <origin xyz="0 0 0" />
      <inertia ixx="0.0001" ixy="0.0" ixz="0.0"
        iyy="0.0001" iyz="0.0"
        izz="0.0001" />
    </inertial>
  </link>

  <!-- add -->
<!-- ===============  Transmission =============== -->
  <transmission name="left_wheel_trans">
    <type>transmission_interface/SimpleTransmission</type>
    <joint name="left_wheel_joint">
      <hardwareInterface>VelocityJointInterface</hardwareInterface>
    </joint>
    <actuator name="left_wheel_motor">
      <hardwareInterface>VelocityJointInterface</hardwareInterface>
      <mechanicalReduction>30</mechanicalReduction>
    </actuator>
  </transmission>
  <transmission name="right_wheel_trans">
    <type>transmission_interface/SimpleTransmission</type>
    <joint name="right_wheel_joint">
      <hardwareInterface>VelocityJointInterface</hardwareInterface>
    </joint>
    <actuator name="right_wheel_motor">
      <hardwareInterface>VelocityJointInterface</hardwareInterface>
      <mechanicalReduction>30</mechanicalReduction>
    </actuator>
  </transmission>

  <!-- =============== Gazebo =============== -->
  <gazebo>
    <plugin name="gazebo_ros_control" filename="libgazebo_ros_control.so">
      <robotNamespace>my_robo</robotNamespace>
    </plugin>
  </gazebo>

  <gazebo reference="base_link">
    <selfCollide>true</selfCollide>
    <mu1 value="0.05" />
    <mu2 value="0.05" />
  </gazebo>

  <gazebo reference="left_wheel_link">
    <selfCollide>true</selfCollide>
    <mu1 value="0.8" />
    <mu2 value="0.8" />
  </gazebo>

  <gazebo reference="right_wheel_link">
    <selfCollide>true</selfCollide>
    <mu1 value="0.8" />
    <mu2 value="0.8" />
  </gazebo>

  <gazebo reference="caster_link">
    <selfCollide>true</selfCollide>
    <!-- This caster is no frictional resistance. -->
    <mu1 value="0.0" />
    <mu2 value="0.0" />
  </gazebo>


  <!-- urg gazebo -->
  <gazebo reference="base_laser_link">
    <sensor type="gpu_ray" name="head_hokuyo_sensor">
      <pose>0 0 0 0 0 0</pose>
      <visualize>false</visualize>
      <update_rate>40</update_rate>
      <ray>
        <scan>
          <horizontal>
            <samples>720</samples>
            <resolution>1</resolution>
            <min_angle>-1.570796</min_angle>
            <max_angle>1.570796</max_angle>
          </horizontal>
        </scan>
        <range>
          <min>0.10</min>
          <max>30.0</max>
          <resolution>0.01</resolution>
        </range>
        <noise>
          <type>gaussian</type>
          <!-- Noise parameters based on published spec for Hokuyo laser
               achieving "+-30mm" accuracy at range < 10m.  A mean of 0.0m and
               stddev of 0.01m will put 99.7% of samples within 0.03m of the true
               reading. -->
          <mean>0.0</mean>
          <stddev>0.01</stddev>
        </noise>
      </ray>
      <plugin name="gazebo_ros_head_hokuyo_controller" filename="libgazebo_ros_gpu_laser.so">
        <topicName>/rrbot/laser/scan</topicName>
        <frameName>base_laser_link</frameName>
      </plugin>
    </sensor>
  </gazebo>

  <!-- openplatform_sobit_mini_description -->
  <material name="red">
    <color rgba="1.0 0.0 0.0 1.0"/>
  </material>
  <material name="green">
    <color rgba="0.0 1.0 0.0 1.0"/>
  </material>
  <material name="blue">
    <color rgba="0.0 0.0 1.0 1.0"/>
  </material>
  <material name="black">
    <color rgba="0.0 0.0 0.0 1.0"/>
  </material>
  <material name="white">
    <color rgba="0.87 0.90 0.87 1.0"/>
  </material>
  <material name="orange">
    <color rgba="1.0 0.4 0.0 1.0"/>
  </material>

  <!-- sobit base -->
  <!-- Link 1 -->
  <link name="link1">
    <collision>
      <origin rpy="0 0 0" xyz="0 0 0.03"/>
      <geometry>
        <box size="0.16 0.16 0.06"/>
      </geometry>
    </collision>
    <visual>
      <origin rpy="0 0 0" xyz="0 0 0.03"/>
      <geometry>
        <box size="0.16 0.16 0.06"/>
      </geometry>
      <material name="black"/>
    </visual>
    <inertial>
      <origin rpy="0 0 0" xyz="0 0 0.03"/>
      <mass value="1"/>
      <inertia ixx="1.0" ixy="0.0" ixz="0.0" iyy="1.0" iyz="0.0" izz="1.0"/>
    </inertial>
  </link>
  <joint name="joint1" type="revolute">
    <parent link="plate_middle_link"/>
    <child link="link1"/>
    <origin rpy="0 0 0" xyz="0 0 0.0"/>
    <axis xyz="0 0 1"/>
    <limit effort="30" lower="-1.57" upper="1.57" velocity="1.571"/>
  </joint>
  <gazebo reference="link1">
    <material>Gazebo/Black</material>
  </gazebo>
  <transmission name="trans1">
    <type>transmission_interface/SimpleTransmission</type>
    <joint name="joint1">
      <hardwareInterface>EffortJointInterface</hardwareInterface>
    </joint>
    <actuator name="motor1">
      <hardwareInterface>EffortJointInterface</hardwareInterface>
      <mechanicalReduction>1</mechanicalReduction>
    </actuator>
  </transmission>

  <joint name="dmmy_joint1" type="fixed">
    <parent link="link1"/>
    <child link="link2"/>
    <origin rpy="0 0 0" xyz="-0.03 0 0.06"/>
    <axis xyz="1 0 0"/>
    <limit effort="30" lower="-2.35" upper="0" velocity="1.571"/>
  </joint>
  <gazebo reference="link2">
    <material>Gazebo/FlatBlack</material>
  </gazebo>
  <transmission name="trans2">
    <type>transmission_interface/SimpleTransmission</type>
    <joint name="dmmy_joint1">
      <hardwareInterface>EffortJointInterface</hardwareInterface>
    </joint>
    <actuator name="dmmy_motor1">
      <hardwareInterface>EffortJointInterface</hardwareInterface>
      <mechanicalReduction>1</mechanicalReduction>
    </actuator>
  </transmission>

  <!-- Link 2 -->
  <link name="link2">
    <collision>
      <origin rpy="0 0 0" xyz="0.0 0.0 0.255"/>
      <geometry>
        <box size="0.02 0.03 0.51"/>
      </geometry>
    </collision>
    <visual>
      <origin rpy="0 0 0" xyz="0.0 0.0 0.255"/>
      <geometry>
        <box size="0.02 0.03 0.51"/>
      </geometry>
      <material name="black"/>
    </visual>
    <inertial>
      <origin rpy="0 0 0" xyz="0.0 0.0 0.255"/>
      <mass value="0.08"/>
      <inertia ixx="1.0" ixy="0.0" ixz="0.0" iyy="1.0" iyz="0.0" izz="1.0"/>
    </inertial>
  </link>
  <gazebo reference="link2">
    <material>Gazebo/Black</material>
  </gazebo>

  <joint name="joint2" type="prismatic">
    <parent link="link2"/>
    <child link="link3"/>
    <origin rpy="0 0 1.57" xyz="0.03 0.0 0.0"/>
    <axis xyz="0 0 1"/>
    <limit effort="30" lower="0" upper="0.31" velocity="1.571"/>
  </joint>
  <gazebo reference="link2">
    <material>Gazebo/Black</material>
  </gazebo>
  <transmission name="trans2">
    <type>transmission_interface/SimpleTransmission</type>
    <joint name="joint2">
      <hardwareInterface>EffortJointInterface</hardwareInterface>
    </joint>
    <actuator name="motor2">
       <hardwareInterface>EffortJointInterface</hardwareInterface>
      <mechanicalReduction>1</mechanicalReduction>
    </actuator>
  </transmission>

  <!-- Link 3 -->
  <link name="link3">
    <collision>
      <origin rpy="0 0 0" xyz="0.0 0 0.2575"/>
      <geometry>
        <box size="0.02 0.02 0.515"/>
      </geometry>
    </collision>
    <visual>
      <origin rpy="0 0 0" xyz="0.0 0 0.2575"/>
      <geometry>
        <box size="0.02 0.02 0.515"/>
      </geometry>
      <material name="black"/>
    </visual>
    <inertial>
      <origin rpy="0 0 0" xyz="0 0 0.2575"/>
      <mass value="0.08"/>
      <inertia ixx="1.0" ixy="0.0" ixz="0.0" iyy="1.0" iyz="0.0" izz="1.0"/>
    </inertial>
  </link>

  <!-- sobit limb Branch -->
  <joint name="dmmy_joint3" type="fixed">
    <parent link="link3"/>
    <child link="link4_left_arm"/>
    <origin rpy="0 0 0" xyz="0.01 0 0.4"/>
    <axis xyz="0 0 1"/>
    <limit effort="30" lower="-0.1" upper="0.1" velocity="1.571"/>
  </joint>

  <joint name="dmmy_joint6" type="fixed">
    <parent link="link3"/>
    <child link="link4_right_arm"/>
    <origin rpy="0 0 0" xyz="-0.01 0 0.4"/>
    <axis xyz="0 0 1"/>
    <limit effort="30" lower="-0.1" upper="0.1" velocity="1.571"/>
  </joint>

  <joint name="dmmy_joint_head" type="fixed">
    <parent link="link3"/>
    <child link="link11_head"/>
    <origin rpy="0 0 0" xyz="0 0 0.515"/>
    <axis xyz="0 0 1"/>
    <limit effort="30" lower="-0.1" upper="0.1" velocity="1.571"/>
  </joint>

  <joint name="dmmy_joint_left_ribs" type="fixed">
    <parent link="link3"/>
    <child link="link14_left_ribs"/>
    <origin rpy="0 0 0" xyz="0.01 0 0.05"/>
    <axis xyz="0 0 1"/>
    <limit effort="30" lower="-0.1" upper="0.1" velocity="1.571"/>
  </joint>

  <joint name="dmmy_joint_right_ribs" type="fixed">
    <parent link="link3"/>
    <child link="link14_right_ribs"/>
    <origin rpy="0 0 0" xyz="-0.01 0 0.05"/>
    <axis xyz="0 0 1"/>
    <limit effort="30" lower="-0.1" upper="0.1" velocity="1.571"/>
  </joint>

  <joint name="dmmy_joint_body" type="fixed">
    <parent link="link3"/>
    <child link="body_link"/>
    <origin rpy="0 0 0" xyz="0 0 0.3"/>
    <axis xyz="0 0 1"/>
    <limit effort="30" lower="-0.1" upper="0.1" velocity="1.571"/>
  </joint>



  <!-- sobit Left_arm-->
  <!-- link4_left_arm -->
  <link name="link4_left_arm">
    <collision>
      <origin rpy="0 0 0" xyz="0.0525 0 0.0"/>
      <geometry>
        <box size="0.105 0.03 0.055"/>
      </geometry>
    </collision>
    <visual>
      <origin rpy="0 0 0" xyz="0.0525 0 0.0"/>
      <geometry>
        <box size="0.105 0.03 0.055"/>
      </geometry>
      <material name="black"/>
    </visual>
    <inertial>
      <origin rpy="0 0 0" xyz="0.0525 0 0.0"/>
      <mass value="0.08"/>
      <inertia ixx="1.0" ixy="0.0" ixz="0.0" iyy="1.0" iyz="0.0" izz="1.0"/>
    </inertial>
  </link>
  <joint name="joint3" type="revolute">
    <parent link="link4_left_arm"/>
    <child link="link5_left_arm"/>
    <origin rpy="0 0 0" xyz="0.105 0 0.02"/>
    <axis xyz="1 0 0"/>
    <limit effort="30" lower="-1.57" upper="0" velocity="1.571"/>
  </joint>
  <gazebo reference="link4_left_arm">
    <material>Gazebo/FlatBlack</material>
  </gazebo>
  <transmission name="trans4_left_arm">
    <type>transmission_interface/SimpleTransmission</type>
    <joint name="joint3">
      <hardwareInterface>EffortJointInterface</hardwareInterface>
    </joint>
    <actuator name="motor3">
      <hardwareInterface>EffortJointInterface</hardwareInterface>
      <mechanicalReduction>1</mechanicalReduction>
    </actuator>
  </transmission>

  <!-- link5_left_arm -->
  <link name="link5_left_arm">
    <collision>
      <origin rpy="0 0 0" xyz="0.034 0 0.0"/>
      <geometry>
        <box size="0.068 0.05 0.04"/>
      </geometry>
    </collision>
    <visual>
      <origin rpy="0 0 0" xyz="0.034 0 0.0"/>
      <geometry>
        <box size="0.068 0.05 0.04"/>
      </geometry>
      <material name="black"/>
    </visual>
    <inertial>
      <origin rpy="0 0 0" xyz="0.034 0 0.0"/>
      <mass value="0.08"/>
      <inertia ixx="1.0" ixy="0.0" ixz="0.0" iyy="1.0" iyz="0.0" izz="1.0"/>
    </inertial>
  </link>
  <gazebo reference="link5_left_arm">
    <material>Gazebo/Black</material>
  </gazebo>
  <joint name="joint4" type="revolute">
    <parent link="link5_left_arm"/>
    <child link="link6_left_arm"/>
    <origin rpy="0 0 0" xyz="0.053 0.0 0.0"/>
    <axis xyz="0 1 0"/>
    <limit effort="30" lower="-3.14" upper="0" velocity="1.571"/>
  </joint>
  <gazebo reference="link5_left_arm">
    <material>Gazebo/Black</material>
  </gazebo>
  <transmission name="trans5_left_arm">
    <type>transmission_interface/SimpleTransmission</type>
    <joint name="joint4">
      <hardwareInterface>EffortJointInterface</hardwareInterface>
    </joint>
    <actuator name="motor4">
      <hardwareInterface>EffortJointInterface</hardwareInterface>
      <mechanicalReduction>1</mechanicalReduction>
    </actuator>
  </transmission>

  <!-- link6_left_arm -->
  <link name="link6_left_arm">
    <collision>
      <origin rpy="0 0 0" xyz="0.0 0 -0.095"/>
      <geometry>
        <box size="0.035 0.05 0.19"/>
      </geometry>
    </collision>
    <visual>
      <origin rpy="0 0 0" xyz="0.0 0 -0.095"/>
      <geometry>
        <box size="0.035 0.05 0.19"/>
      </geometry>
      <material name="black"/>
    </visual>
    <inertial>
      <origin rpy="0 0 0" xyz="0 0 -0.095"/>
      <mass value="0.08"/>
      <inertia ixx="1.0" ixy="0.0" ixz="0.0" iyy="1.0" iyz="0.0" izz="1.0"/>
    </inertial>
  </link>
  <joint name="joint5" type="revolute">
    <parent link="link6_left_arm"/>
    <child link="link7_left_arm"/>
    <origin rpy="0 0 0" xyz="0 0 -0.19"/>
    <axis xyz="0 1 0"/>
    <limit effort="30" lower="-1.57" upper="1.57" velocity="1.571"/>
  </joint>
  <gazebo reference="link6_left_arm">
    <material>Gazebo/Black</material>
  </gazebo>
  <transmission name="trans6_left_arm">
    <type>transmission_interface/SimpleTransmission</type>
    <joint name="joint5">
      <hardwareInterface>EffortJointInterface</hardwareInterface>
    </joint>
    <actuator name="motor5">
      <hardwareInterface>EffortJointInterface</hardwareInterface>
      <mechanicalReduction>1</mechanicalReduction>
    </actuator>
  </transmission>

  <!-- link7_left_arm -->
  <link name="link7_left_arm">
    <collision>
      <origin rpy="0 0 0" xyz="0.0 0 -0.035"/>
      <geometry>
        <box size="0.06 0.04 0.07"/>
      </geometry>
    </collision>
    <visual>
      <origin rpy="0 0 0" xyz="0.0 0 -0.035"/>
      <geometry>
        <box size="0.06 0.04 0.07"/>
      </geometry>
      <material name="black"/>
    </visual>
    <inertial>
      <origin rpy="0 0 0" xyz="0 0 -0.035"/>
      <mass value="0.08"/>
      <inertia ixx="1.0" ixy="0.0" ixz="0.0" iyy="1.0" iyz="0.0" izz="1.0"/>
    </inertial>
  </link>
  <gazebo reference="link7_left_arm">
    <material>Gazebo/Black</material>
  </gazebo>
  <joint name="dmmy_joint4" type="fixed">
    <parent link="link7_left_arm"/>
    <child link="link8_left_arm"/>
    <origin rpy="0 0 0" xyz="0 0 -0.05"/>
    <axis xyz="0 1 0"/>
    <limit effort="30" lower="-1.57" upper="1.57" velocity="1.571"/>
  </joint>

  <!-- link8_left_arm -->
  <link name="link8_left_arm">
    <collision>
      <origin rpy="0 3.14 0" xyz="0.0 0 0"/>
      <geometry>
        <mesh filename="package://sobit_mini_description/model/dae/Manipulator_X4_Gripper_fix.dae"/>
      </geometry>
    </collision>
    <visual>
      <origin rpy="0 3.14 0" xyz="0.0 0 0"/>
      <geometry>
        <mesh filename="package://sobit_mini_description/model/dae/Manipulator_X4_Gripper_fix.dae"/>
      </geometry>
      <material name="black"/>
    </visual>
    <inertial>
      <origin rpy="0 3.14 0" xyz="0 0 0"/>
      <mass value="0.08"/>
      <inertia ixx="1.0" ixy="0.0" ixz="0.0" iyy="1.0" iyz="0.0" izz="1.0"/>
    </inertial>
  </link>

  <!-- link9_left_arm_left_finger -->
  <link name="link9_left_arm_left_finger">
    <collision>
      <origin rpy="0 3.14 3.14" xyz="0 0 0"/>
      <geometry>
        <mesh filename="package://sobit_mini_description/model/dae/ManipulatorX4_Finger_left.dae"/>
      </geometry>
    </collision>
    <visual>
      <origin rpy="0 3.14 3.14" xyz="0 0 0"/>
      <geometry>
        <mesh filename="package://sobit_mini_description/model/dae/ManipulatorX4_Finger_left.dae"/>
      </geometry>
      <material name="black">
        <color rgba="0.0 0.0 0.0 1.0"/>
      </material>
    </visual>
    <inertial>
      <origin rpy="0 3.14 3.14" xyz="0 0 0"/>
      <mass value="0.08"/>
      <inertia ixx="1.0" ixy="0.0" ixz="0.0" iyy="1.0" iyz="0.0" izz="1.0"/>
    </inertial>
  </link>
  <joint name="link9_left_arm_left_finger_joint" type="revolute">
    <parent link="link8_left_arm"/>
    <child link="link9_left_arm_left_finger"/>
        <origin rpy="0 0 0" xyz="0 0.018 -0.043"/>
        <axis xyz="1 0 0"/>
    <limit lower="-1" upper="0.0" effort="1" velocity="1" />
  </joint>
  <gazebo reference="link9_left_arm_left_finger">
    <material>Gazebo/Black</material>
  </gazebo>
  <transmission name="trans_link9_left_arm_left_finger">
    <type>transmission_interface/SimpleTransmission</type>
    <joint name="joint6">
      <hardwareInterface>EffortJointInterface</hardwareInterface>
    </joint>
    <actuator name="motor6">
      <hardwareInterface>EffortJointInterface</hardwareInterface>
      <mechanicalReduction>1</mechanicalReduction>
    </actuator>
  </transmission>

  <!-- link10_left_arm_right_finger -->
  <link name="link10_left_arm_right_finger">
    <collision>
      <origin rpy="0 3.14 0" xyz="0 0 0"/>
      <geometry>
        <mesh filename="package://sobit_mini_description/model/dae/ManipulatorX4_Finger_left.dae"/>
      </geometry>
    </collision>
    <visual>
      <origin rpy="0 3.14 0" xyz="0 0 0"/>
      <geometry>
        <mesh filename="package://sobit_mini_description/model/dae/ManipulatorX4_Finger_left.dae"/>
      </geometry>
      <material name="black">
        <color rgba="0.0 0.0 0.0 1.0"/>
      </material>
    </visual>
    <inertial>
      <origin rpy="0 3.14 0" xyz="0 0 0"/>
      <mass value="0.08"/>
      <inertia ixx="1.0" ixy="0.0" ixz="0.0" iyy="1.0" iyz="0.0" izz="1.0"/>
    </inertial>
  </link>
  <joint name="link10_left_arm_right_finger_joint" type="revolute">
    <parent link="link8_left_arm"/>
    <child link="link10_left_arm_right_finger"/>
        <origin rpy="0 0 0" xyz="0 -0.018 -0.043"/>
        <axis xyz="1 0 0"/>
    <limit lower="0.0" upper="1" effort="1" velocity="1" />
  </joint>
  <gazebo reference="link10_left_arm_right_finger">
    <material>Gazebo/Black</material>
  </gazebo>
  <transmission name="trans_link10_left_arm_right_finger">
    <type>transmission_interface/SimpleTransmission</type>
    <joint name="link10_left_arm_right_finger_joint">
      <hardwareInterface>EffortJointInterface</hardwareInterface>
    </joint>
    <actuator name="motor7">
      <hardwareInterface>EffortJointInterface</hardwareInterface>
      <mechanicalReduction>1</mechanicalReduction>
    </actuator>
  </transmission>

  <!-- sobit Right_arm -->
  <!-- link4_right_arm -->
  <link name="link4_right_arm">
    <collision>
      <origin rpy="0 0 0" xyz="-0.0525 0 0.0"/>
      <geometry>
        <box size="0.105 0.03 0.055"/>
      </geometry>
    </collision>
    <visual>
      <origin rpy="0 0 0" xyz="-0.0525 0 0.0"/>
      <geometry>
        <box size="0.105 0.03 0.055"/>
      </geometry>
      <material name="black"/>
    </visual>
    <inertial>
      <origin rpy="0 0 0" xyz="-0.0525 0 0.0"/>
      <mass value="0.08"/>
      <inertia ixx="1.0" ixy="0.0" ixz="0.0" iyy="1.0" iyz="0.0" izz="1.0"/>
    </inertial>
  </link>
  <joint name="joint7" type="revolute">
    <parent link="link4_right_arm"/>
    <child link="link5_right_arm"/>
    <origin rpy="0 0 0" xyz="-0.105 0 0.02"/>
    <axis xyz="1 0 0"/>
    <limit effort="30" lower="-1.57" upper="0" velocity="1.571"/>
  </joint>
  <gazebo reference="link4_right_arm">
    <material>Gazebo/FlatBlack</material>
  </gazebo>
  <transmission name="trans_link4_right_arm">
    <type>transmission_interface/SimpleTransmission</type>
    <joint name="joint7">
      <hardwareInterface>EffortJointInterface</hardwareInterface>
    </joint>
    <actuator name="motor7">
      <hardwareInterface>EffortJointInterface</hardwareInterface>
      <mechanicalReduction>1</mechanicalReduction>
    </actuator>
  </transmission>

  <!-- link5_right_arm -->
  <link name="link5_right_arm">
    <collision>
      <origin rpy="0 0 0" xyz="-0.034 0 0.0"/>
      <geometry>
        <box size="0.068 0.05 0.04"/>
      </geometry>
    </collision>
    <visual>
      <origin rpy="0 0 0" xyz="-0.034 0 0.0"/>
      <geometry>
        <box size="0.068 0.05 0.04"/>
      </geometry>
      <material name="black"/>
    </visual>
    <inertial>
      <origin rpy="0 0 0" xyz="-0.034 0 0.0"/>
      <mass value="0.08"/>
      <inertia ixx="1.0" ixy="0.0" ixz="0.0" iyy="1.0" iyz="0.0" izz="1.0"/>
    </inertial>
  </link>
  <gazebo reference="link5_right_arm">
    <material>Gazebo/Black</material>
  </gazebo>
  <joint name="joint8" type="revolute">
    <parent link="link5_right_arm"/>
    <child link="link6_right_arm"/>
    <origin rpy="0 0 0" xyz="-0.053 0.0 0.0"/>
    <axis xyz="0 1 0"/>
    <limit effort="30" lower="0" upper="3.14" velocity="1.571"/>
  </joint>
  <transmission name="trans_link5_right_arm">
    <type>transmission_interface/SimpleTransmission</type>
    <joint name="joint8">
      <hardwareInterface>EffortJointInterface</hardwareInterface>
    </joint>
    <actuator name="motor8">
      <hardwareInterface>EffortJointInterface</hardwareInterface>
      <mechanicalReduction>1</mechanicalReduction>
    </actuator>
  </transmission>

  <!-- link6_right_arm -->
  <link name="link6_right_arm">
    <collision>
      <origin rpy="0 0 0" xyz="0.0 0 -0.095"/>
      <geometry>
        <box size="0.035 0.05 0.19"/>
      </geometry>
    </collision>
    <visual>
      <origin rpy="0 0 0" xyz="0.0 0 -0.095"/>
      <geometry>
        <box size="0.035 0.05 0.19"/>
      </geometry>
      <material name="black"/>
    </visual>
    <inertial>
      <origin rpy="0 0 0" xyz="0 0 -0.095"/>
      <mass value="0.08"/>
      <inertia ixx="1.0" ixy="0.0" ixz="0.0" iyy="1.0" iyz="0.0" izz="1.0"/>
    </inertial>
  </link>
  <joint name="joint9" type="revolute">
    <parent link="link6_right_arm"/>
    <child link="link7_right_arm"/>
    <origin rpy="0 0 0" xyz="0 0 -0.19"/>
    <axis xyz="0 1 0"/>
    <limit effort="30" lower="-1.57" upper="1.57" velocity="1.571"/>
  </joint>
  <gazebo reference="link6_right_arm">
    <material>Gazebo/Black</material>
  </gazebo>
  <transmission name="trans_link6_right_arm">
    <type>transmission_interface/SimpleTransmission</type>
    <joint name="joint9">
      <hardwareInterface>EffortJointInterface</hardwareInterface>
    </joint>
    <actuator name="motor9">
      <hardwareInterface>EffortJointInterface</hardwareInterface>
      <mechanicalReduction>1</mechanicalReduction>
    </actuator>
  </transmission>

  <!-- link7_right_arm -->
  <link name="link7_right_arm">
    <collision>
      <origin rpy="0 0 0" xyz="0.0 0 -0.035"/>
      <geometry>
        <box size="0.06 0.04 0.07"/>
      </geometry>
    </collision>
    <visual>
      <origin rpy="0 0 0" xyz="0.0 0 -0.035"/>
      <geometry>
        <box size="0.06 0.04 0.07"/>
      </geometry>
      <material name="black"/>
    </visual>
    <inertial>
      <origin rpy="0 0 0" xyz="0 0 -0.035"/>
      <mass value="0.08"/>
      <inertia ixx="1.0" ixy="0.0" ixz="0.0" iyy="1.0" iyz="0.0" izz="1.0"/>
    </inertial>
  </link>
  <gazebo reference="link7_right_arm">
    <material>Gazebo/Black</material>
  </gazebo>
  <joint name="dmmy_joint7" type="fixed">
    <parent link="link7_right_arm"/>
    <child link="link8_right_arm"/>
    <origin rpy="0 0 0" xyz="0 0 -0.05"/>
    <axis xyz="0 1 0"/>
    <limit effort="30" lower="-1.57" upper="1.57" velocity="1.571"/>
  </joint>

  <!-- link8_right_arm -->
  <link name="link8_right_arm">
    <collision>
      <origin rpy="0 3.14 0" xyz="0 0 0"/>
      <geometry>
        <mesh filename="package://sobit_mini_description/model/dae/Manipulator_X4_Gripper_fix.dae"/>
      </geometry>
    </collision>
    <visual>
    <origin rpy="0 3.14 0" xyz="0 0 0"/>
      <geometry>
        <mesh filename="package://sobit_mini_description/model/dae/Manipulator_X4_Gripper_fix.dae"/>
      </geometry>
      <material name="black"/>
    </visual>
    <inertial>
      <origin rpy="0 3.14 0" xyz="0 0 0"/>
      <mass value="0.08"/>
      <inertia ixx="1.0" ixy="0.0" ixz="0.0" iyy="1.0" iyz="0.0" izz="1.0"/>
    </inertial>
  </link>

  <!-- link9_right_arm_left_finger -->
  <link name="link9_right_arm_left_finger">
    <collision>
      <origin rpy="0 3.14 3.14" xyz="0 0 0"/>
      <geometry>
        <mesh filename="package://sobit_mini_description/model/dae/ManipulatorX4_Finger_left.dae"/>
      </geometry>
    </collision>
    <visual>
      <origin rpy="0 3.14 3.14" xyz="0 0 0"/>
      <geometry>
        <mesh filename="package://sobit_mini_description/model/dae/ManipulatorX4_Finger_left.dae"/>
      </geometry>
      <material name="black">
        <color rgba="0.0 0.0 0.0 1.0"/>
      </material>
    </visual>
    <inertial>
      <origin rpy="0 3.14 3.14" xyz="0 0 0"/>
      <mass value="0.08"/>
      <inertia ixx="1.0" ixy="0.0" ixz="0.0" iyy="1.0" iyz="0.0" izz="1.0"/>
    </inertial>
  </link>
  <joint name="link9_right_arm_left_finger_joint" type="revolute">
  	<parent link="link8_right_arm"/>
  	<child link="link9_right_arm_left_finger"/>
        <origin rpy="0 0 0" xyz="0 0.018 -0.043"/>
        <axis xyz="1 0 0"/>
  	<limit lower="-1" upper="0" effort="1" velocity="1" />
  </joint>
  <gazebo reference="right_arm_left_finger">
    <material>Gazebo/Black</material>
  </gazebo>
  <transmission name="trans_link9_right_arm_left_finger">
    <type>transmission_interface/SimpleTransmission</type>
    <joint name="link9_right_arm_left_finger_joint">
      <hardwareInterface>EffortJointInterface</hardwareInterface>
    </joint>
    <actuator name="motor_link9_right_arm_left_finger">
      <hardwareInterface>EffortJointInterface</hardwareInterface>
      <mechanicalReduction>1</mechanicalReduction>
    </actuator>
  </transmission>

  <!-- link10_right_arm_right_finger -->
  <link name="link10_right_arm_right_finger">
    <collision>
      <origin rpy="0 3.14 0" xyz="0 0 0"/>
      <geometry>
        <mesh filename="package://sobit_mini_description/model/dae/ManipulatorX4_Finger_left.dae"/>
      </geometry>
    </collision>
    <visual>
      <origin rpy="0 3.14 0" xyz="0 0 0"/>
      <geometry>
        <mesh filename="package://sobit_mini_description/model/dae/ManipulatorX4_Finger_left.dae"/>
      </geometry>
      <material name="black">
        <color rgba="0.0 0.0 0.0 1.0"/>
      </material>
    </visual>
    <inertial>
      <origin rpy="0 3.14 0" xyz="0 0 0"/>
      <mass value="0.08"/>
      <inertia ixx="1.0" ixy="0.0" ixz="0.0" iyy="1.0" iyz="0.0" izz="1.0"/>
    </inertial>
  </link>
  <joint name="link10_right_arm_right_finger_joint" type="revolute">
  	<parent link="link8_right_arm"/>
  	<child link="link10_right_arm_right_finger"/>
        <origin rpy="0 0 0" xyz="0 -0.018 -0.043"/>
        <axis xyz="1 0 0"/>
  	<limit lower="0.0" upper="1" effort="1" velocity="1" />
  </joint>
  <gazebo reference="link10_right_arm_right_finger">
    <material>Gazebo/Black</material>
  </gazebo>
  <transmission name="trans_link10_right_arm_right_finger">
    <type>transmission_interface/SimpleTransmission</type>
    <joint name="link10_right_arm_right_finger_joint">
      <hardwareInterface>EffortJointInterface</hardwareInterface>
    </joint>
    <actuator name="motor_link10_right_arm_right_finger">
      <hardwareInterface>EffortJointInterface</hardwareInterface>
      <mechanicalReduction>1</mechanicalReduction>
    </actuator>
  </transmission>



  <!-- sobit Head -->
  <!-- Link 11_head -->
  <link name="link11_head">
    <collision>
      <origin rpy="0 0 0" xyz="0 0.015 0.0225"/>
      <geometry>
        <box size="0.03 0.05 0.045"/>
      </geometry>
    </collision>
    <visual>
      <origin rpy="0 0 0" xyz="0 0.015 0.0225"/>
      <geometry>
        <box size="0.03 0.05 0.045"/>
      </geometry>
      <material name="black"/>
    </visual>
    <inertial>
      <origin rpy="0 0 0" xyz="0 -0.015 0.0225"/>
      <mass value="0.08"/>
      <inertia ixx="1.0" ixy="0.0" ixz="0.0" iyy="1.0" iyz="0.0" izz="1.0"/>
    </inertial>
  </link>
  <joint name="joint10" type="revolute">
    <parent link="link11_head"/>
    <child link="link12_head"/>
    <origin rpy="0 0 0" xyz="0 -0.0 0.045"/>
    <axis xyz="0 0 1"/>
    <limit effort="30" lower="-3.14" upper="3.14" velocity="1.571"/>
  </joint>
  <gazebo reference="link11_head">
    <material>Gazebo/FlatBlack</material>
  </gazebo>
  <transmission name="trans11_head">
    <type>transmission_interface/SimpleTransmission</type>
    <joint name="joint10">
      <hardwareInterface>EffortJointInterface</hardwareInterface>
    </joint>
    <actuator name="motor10">
      <hardwareInterface>EffortJointInterface</hardwareInterface>
      <mechanicalReduction>1</mechanicalReduction>
    </actuator>
  </transmission>

  <!-- Link 12_head -->
  <link name="link12_head">
    <collision>
      <origin rpy="0 0 0" xyz="0 0 0.015"/>
      <geometry>
        <box size="0.04 0.023 0.03"/>
      </geometry>
    </collision>
    <visual>
      <origin rpy="0 0 0" xyz="0 0 0.015"/>
      <geometry>
        <box size="0.04 0.023 0.03"/>
      </geometry>
      <material name="black"/>
    </visual>
    <inertial>
      <origin rpy="0 0 0" xyz="0 0 0.015"/>
      <mass value="0.08"/>
      <inertia ixx="1.0" ixy="0.0" ixz="0.0" iyy="1.0" iyz="0.0" izz="1.0"/>
    </inertial>
  </link>
  <gazebo reference="link12_head">
    <material>Gazebo/Black</material>
  </gazebo>
  <joint name="joint11" type="revolute">
    <parent link="link12_head"/>
    <child link="link13_head"/>
    <origin rpy="0 0 0" xyz="0 0 0.03"/>
    <axis xyz="1 0 0"/>
    <limit effort="30" lower="-1.57" upper="1.57" velocity="1.571"/>
  </joint>
  <transmission name="trans_link12_head">
    <type>transmission_interface/SimpleTransmission</type>
    <joint name="joint11">
      <hardwareInterface>EffortJointInterface</hardwareInterface>
    </joint>
    <actuator name="motor11">
      <hardwareInterface>EffortJointInterface</hardwareInterface>
      <mechanicalReduction>1</mechanicalReduction>
    </actuator>
  </transmission>

  <!-- Link 13_head -->
  <link name="link13_head">
    <collision>
      <origin rpy="0 0 0" xyz="0 0 0.07"/>
      <geometry>
        <box size="0.035 0.03 0.14"/>
      </geometry>
    </collision>
    <visual>
      <origin rpy="0 0 0" xyz="0 0 0.07"/>
      <geometry>
        <box size="0.035 0.03 0.14"/>
      </geometry>
      <material name="black"/>
    </visual>
    <inertial>
      <origin rpy="0 0 0" xyz="0 0 0.07"/>
      <mass value="0.08"/>
      <inertia ixx="1.0" ixy="0.0" ixz="0.0" iyy="1.0" iyz="0.0" izz="1.0"/>
    </inertial>
  </link>
  <gazebo reference="link13_head">
    <material>Gazebo/Black</material>
  </gazebo>
  <joint name="dmmy_conect_joint_3" type="fixed">
    <parent link="link13_head"/>
    <child link="xtion"/>
    <origin rpy="0 0 -1.57" xyz="0 0 0.14"/>
    <axis xyz="0 1 0"/>
    <limit effort="30" lower="-1.57" upper="1.57" velocity="1.571"/>
  </joint>

  <!-- xtion -->
  <link name="xtion">
    <visual>
      <origin xyz="-0.0 0.0 0" rpy="0 0 0"/>
      <geometry>
        <mesh filename="package://turtlebot_description/meshes/sensors/xtion_pro_camera.dae"/>
      </geometry>
    </visual>
    <collision>
      <origin xyz="0.0 0.0 0.0" rpy="0 0 0" />
      <geometry>
      <box size="0.0730 0.2760 0.0720"/>
    </geometry>
    </collision>
    <inertial>
      <mass value="0.170" />
      <origin xyz="0 0 0" />
      <inertia ixx="0.001152600" ixy="0.0" ixz="0.0"
               iyy="0.000148934" iyz="0.0"
               izz="0.001154654" />
    </inertial>
  </link>

  <!-- rgb_link -->
  <link name="rgb_link"/>
  <joint name="rgb_link_xtion_joint" type="fixed">
    <parent link="xtion"/>
    <child link="rgb_link"/>
    <origin rpy="-1.57 0 -1.57" xyz="0 0.0205 0"/>
    <axis xyz="0 0 1"/>
    <limit effort="30" lower="-3.14" upper="3.14" velocity="1.571"/>
  </joint>

  <!-- depth_link -->
  <link name="depth_link"/>
  <joint name="depth_link_xtion_joint" type="fixed">
    <parent link="xtion"/>
    <child link="depth_link"/>
    <origin rpy="-1.57 0 -1.57" xyz="0 0.0475 0"/>
    <axis xyz="0 0 1"/>
    <limit effort="30" lower="-3.14" upper="3.14" velocity="1.571"/>
  </joint>



  <!-- sobit Ribs -->
  <!-- link14_left_ribs -->
  <link name="link14_left_ribs">
    <collision>
      <origin rpy="0 0 0" xyz="0.07 0 0.0075"/>
      <geometry>
        <box size="0.14 0.015 0.015"/>
      </geometry>
    </collision>
    <visual>
      <origin rpy="0 0 0" xyz="0.07 0 0.0075"/>
      <geometry>
        <box size="0.14 0.015 0.015"/>
      </geometry>
      <material name="black"/>
    </visual>
    <inertial>
      <origin rpy="0 0 0" xyz="0.07 0 0.0075"/>
      <mass value="0.08"/>
      <inertia ixx="1.0" ixy="0.0" ixz="0.0" iyy="1.0" iyz="0.0" izz="1.0"/>
    </inertial>
  </link>

  <!-- link14_right_ribs -->
  <link name="link14_right_ribs">
    <collision>
      <origin rpy="0 0 0" xyz="-0.07 0 0.0075"/>
      <geometry>
        <box size="0.14 0.015 0.015"/>
      </geometry>
    </collision>
    <visual>
      <origin rpy="0 0 0" xyz="-0.07 0 0.0075"/>
      <geometry>
        <box size="0.14 0.015 0.015"/>
      </geometry>
      <material name="black"/>
    </visual>
    <inertial>
      <origin rpy="0 0 0" xyz="-0.07 0 0.0075"/>
      <mass value="0.08"/>
      <inertia ixx="1.0" ixy="0.0" ixz="0.0" iyy="1.0" iyz="0.0" izz="1.0"/>
    </inertial>
  </link>



  <!-- sobit Body -->
  <link name="body_link">
    <collision>
      <origin rpy="0 0 0" xyz="0 0 0"/>
      <geometry>
        <mesh filename="package://sobit_mini_description/model/dae/mini_sobit_body_size_fix.dae"/>
      </geometry>
    </collision>
    <visual>
      <origin rpy="0 0 0" xyz="0 0 0"/>
      <geometry>
        <mesh filename="package://sobit_mini_description/model/dae/mini_sobit_body_size_fix.dae"/>
      </geometry>
      <material name="black">
        <color rgba="0.0 0.0 0.0 1.0"/>
      </material>
    </visual>
    <inertial>
      <origin rpy="0 0 0" xyz="0 0 0"/>
      <mass value="0.08"/>
      <inertia ixx="1.0" ixy="0.0" ixz="0.0" iyy="1.0" iyz="0.0" izz="1.0"/>
    </inertial>
  </link>



  <gazebo>
    <plugin name="gazebo_ros_control" filename="libgazebo_ros_control.so">
      <robotNamespace>/sobit_mini_description</robotNamespace>
    </plugin>
  </gazebo>

</robot>
